Workbook
Name TypeSeanceListe: Listes!$A$2:$A$19

Sheet Dashboard
A1: DASHBOARD - SUIVI DE LA CHARGE D'ENTRAÎNEMENT DE L'EFFECTIF
A3: =CONCATENATE("Saison : ",TEXT(Paramètres!B4,"dd/mm/yyyy")," au ",TEXT(Paramètres!B5,"dd/mm/yyyy")," — Aujourd'hui : ",TEXT(TODAY(),"dddd dd mmmm yyyy")) -> #VALUE!
A5: NOMBRE D'ATHLÈTES | C5: CHARGE TOTALE GROUPE (7j) | E5: CHARGE MOYENNE (7j) | G5: ACWR MOYEN | I5: FATIGUE MOYENNE | K5: ATHLÈTES EN ALERTE
A6: =COUNTA(B26:B55) -> 30 | C6: =SUM(C26:C55) -> 7.54 | E6: =IFERROR(AVERAGE(C26:C55),0) -> 0.25133333 | G6: =IFERROR(AVERAGE(E26:E55),0) -> 0.77703349 | I6: =IFERROR(AVERAGE(F26:F55),0) -> 67.162172 | K6: =COUNTIF(G26:G55,"Danger")+COUNTIF(G26:G55,"Attention") -> 1
A9: ACCÈS RAPIDE AUX FICHES ATHLÈTES
A10: A1 | B10: A2 | C10: A3 | D10: A4 | E10: A5 | F10: A6 | G10: A7 | H10: A8 | I10: A9 | J10: A10
A11: A11 | B11: A12 | C11: A13 | D11: A14 | E11: A15 | F11: A16 | G11: A17 | H11: A18 | I11: A19 | J11: A20
A12: A21 | B12: A22 | C12: A23 | D12: A24 | E12: A25 | F12: A26 | G12: A27 | H12: A28 | I12: A29 | J12: A30
A14: Cliquer sur un numéro pour ouvrir la fiche de l'athlète correspondant.
A25: N° | B25: Athlète | C25: Charge aiguë (7j) | D25: Charge chronique (28j) | E25: ACWR | F25: Fatigue | G25: Alerte | H25: Fiche
A26: 1 | B26: ='Athlète 1'!$G$3 -> Athlète 1 | C26: =IFERROR(INDEX('Athlète 1'!$J$6:$J$171,MATCH(TODAY(),'Athlète 1'!$A$6:$A$171,0)),"") -> 7.54 | D26: =IFERROR(INDEX('Athlète 1'!$K$6:$K$171,MATCH(TODAY(),'Athlète 1'!$A$6:$A$171,0)),"") -> 9.7035714 | E26: =IFERROR(INDEX('Athlète 1'!$L$6:$L$171,MATCH(TODAY(),'Athlète 1'!$A$6:$A$171,0)),"") -> 0.77703349 | F26: =IFERROR(INDEX('Athlète 1'!$M$6:$M$171,MATCH(TODAY(),'Athlète 1'!$A$6:$A$171,0)),"") -> 2014.8652 | G26: =IF(E26="","",IF(OR(E26<0.5,E26>1.5),"Danger",IF(OR(E26<0.8,E26>1.3),"Attention","OK"))) -> Attention | H26: Ouvrir ➜
A27: 2 | B27: ='Athlète 2'!$G$3 -> Athlète 2 | C27: =IFERROR(INDEX('Athlète 2'!$J$6:$J$171,MATCH(TODAY(),'Athlète 2'!$A$6:$A$171,0)),"") -> 0 | D27: =IFERROR(INDEX('Athlète 2'!$K$6:$K$171,MATCH(TODAY(),'Athlète 2'!$A$6:$A$171,0)),"") -> 0 | E27: =IFERROR(INDEX('Athlète 2'!$L$6:$L$171,MATCH(TODAY(),'Athlète 2'!$A$6:$A$171,0)),"") | F27: =IFERROR(INDEX('Athlète 2'!$M$6:$M$171,MATCH(TODAY(),'Athlète 2'!$A$6:$A$171,0)),"") -> 0 | G27: =IF(E27="","",IF(OR(E27<0.5,E27>1.5),"Danger",IF(OR(E27<0.8,E27>1.3),"Attention","OK"))) | H27: Ouvrir ➜
A28: 3 | B28: ='Athlète 3'!$G$3 -> Athlète 3 | C28: =IFERROR(INDEX('Athlète 3'!$J$6:$J$171,MATCH(TODAY(),'Athlète 3'!$A$6:$A$171,0)),"") -> 0 | D28: =IFERROR(INDEX('Athlète 3'!$K$6:$K$171,MATCH(TODAY(),'Athlète 3'!$A$6:$A$171,0)),"") -> 0 | E28: =IFERROR(INDEX('Athlète 3'!$L$6:$L$171,MATCH(TODAY(),'Athlète 3'!$A$6:$A$171,0)),"") | F28: =IFERROR(INDEX('Athlète 3'!$M$6:$M$171,MATCH(TODAY(),'Athlète 3'!$A$6:$A$171,0)),"") -> 0 | G28: =IF(E28="","",IF(OR(E28<0.5,E28>1.5),"Danger",IF(OR(E28<0.8,E28>1.3),"Attention","OK"))) | H28: Ouvrir ➜
A29: 4 | B29: ='Athlète 4'!$G$3 -> Athlète 4 | C29: =IFERROR(INDEX('Athlète 4'!$J$6:$J$171,MATCH(TODAY(),'Athlète 4'!$A$6:$A$171,0)),"") -> 0 | D29: =IFERROR(INDEX('Athlète 4'!$K$6:$K$171,MATCH(TODAY(),'Athlète 4'!$A$6:$A$171,0)),"") -> 0 | E29: =IFERROR(INDEX('Athlète 4'!$L$6:$L$171,MATCH(TODAY(),'Athlète 4'!$A$6:$A$171,0)),"") | F29: =IFERROR(INDEX('Athlète 4'!$M$6:$M$171,MATCH(TODAY(),'Athlète 4'!$A$6:$A$171,0)),"") -> 0 | G29: =IF(E29="","",IF(OR(E29<0.5,E29>1.5),"Danger",IF(OR(E29<0.8,E29>1.3),"Attention","OK"))) | H29: Ouvrir ➜
A30: 5 | B30: ='Athlète 5'!$G$3 -> Athlète 5 | C30: =IFERROR(INDEX('Athlète 5'!$J$6:$J$171,MATCH(TODAY(),'Athlète 5'!$A$6:$A$171,0)),"") -> 0 | D30: =IFERROR(INDEX('Athlète 5'!$K$6:$K$171,MATCH(TODAY(),'Athlète 5'!$A$6:$A$171,0)),"") -> 0 | E30: =IFERROR(INDEX('Athlète 5'!$L$6:$L$171,MATCH(TODAY(),'Athlète 5'!$A$6:$A$171,0)),"") | F30: =IFERROR(INDEX('Athlète 5'!$M$6:$M$171,MATCH(TODAY(),'Athlète 5'!$A$6:$A$171,0)),"") -> 0 | G30: =IF(E30="","",IF(OR(E30<0.5,E30>1.5),"Danger",IF(OR(E30<0.8,E30>1.3),"Attention","OK"))) | H30: Ouvrir ➜
A31: 6 | B31: ='Athlète 6'!$G$3 -> Athlète 6 | C31: =IFERROR(INDEX('Athlète 6'!$J$6:$J$171,MATCH(TODAY(),'Athlète 6'!$A$6:$A$171,0)),"") -> 0 | D31: =IFERROR(INDEX('Athlète 6'!$K$6:$K$171,MATCH(TODAY(),'Athlète 6'!$A$6:$A$171,0)),"") -> 0 | E31: =IFERROR(INDEX('Athlète 6'!$L$6:$L$171,MATCH(TODAY(),'Athlète 6'!$A$6:$A$171,0)),"") | F31: =IFERROR(INDEX('Athlète 6'!$M$6:$M$171,MATCH(TODAY(),'Athlète 6'!$A$6:$A$171,0)),"") -> 0 | G31: =IF(E31="","",IF(OR(E31<0.5,E31>1.5),"Danger",IF(OR(E31<0.8,E31>1.3),"Attention","OK"))) | H31: Ouvrir ➜
A32: 7 | B32: ='Athlète 7'!$G$3 -> Athlète 7 | C32: =IFERROR(INDEX('Athlète 7'!$J$6:$J$171,MATCH(TODAY(),'Athlète 7'!$A$6:$A$171,0)),"") -> 0 | D32: =IFERROR(INDEX('Athlète 7'!$K$6:$K$171,MATCH(TODAY(),'Athlète 7'!$A$6:$A$171,0)),"") -> 0 | E32: =IFERROR(INDEX('Athlète 7'!$L$6:$L$171,MATCH(TODAY(),'Athlète 7'!$A$6:$A$171,0)),"") | F32: =IFERROR(INDEX('Athlète 7'!$M$6:$M$171,MATCH(TODAY(),'Athlète 7'!$A$6:$A$171,0)),"") -> 0 | G32: =IF(E32="","",IF(OR(E32<0.5,E32>1.5),"Danger",IF(OR(E32<0.8,E32>1.3),"Attention","OK"))) | H32: Ouvrir ➜
A33: 8 | B33: ='Athlète 8'!$G$3 -> Athlète 8 | C33: =IFERROR(INDEX('Athlète 8'!$J$6:$J$171,MATCH(TODAY(),'Athlète 8'!$A$6:$A$171,0)),"") -> 0 | D33: =IFERROR(INDEX('Athlète 8'!$K$6:$K$171,MATCH(TODAY(),'Athlète 8'!$A$6:$A$171,0)),"") -> 0 | E33: =IFERROR(INDEX('Athlète 8'!$L$6:$L$171,MATCH(TODAY(),'Athlète 8'!$A$6:$A$171,0)),"") | F33: =IFERROR(INDEX('Athlète 8'!$M$6:$M$171,MATCH(TODAY(),'Athlète 8'!$A$6:$A$171,0)),"") -> 0 | G33: =IF(E33="","",IF(OR(E33<0.5,E33>1.5),"Danger",IF(OR(E33<0.8,E33>1.3),"Attention","OK"))) | H33: Ouvrir ➜
A34: 9 | B34: ='Athlète 9'!$G$3 -> Athlète 9 | C34: =IFERROR(INDEX('Athlète 9'!$J$6:$J$171,MATCH(TODAY(),'Athlète 9'!$A$6:$A$171,0)),"") -> 0 | D34: =IFERROR(INDEX('Athlète 9'!$K$6:$K$171,MATCH(TODAY(),'Athlète 9'!$A$6:$A$171,0)),"") -> 0 | E34: =IFERROR(INDEX('Athlète 9'!$L$6:$L$171,MATCH(TODAY(),'Athlète 9'!$A$6:$A$171,0)),"") | F34: =IFERROR(INDEX('Athlète 9'!$M$6:$M$171,MATCH(TODAY(),'Athlète 9'!$A$6:$A$171,0)),"") -> 0 | G34: =IF(E34="","",IF(OR(E34<0.5,E34>1.5),"Danger",IF(OR(E34<0.8,E34>1.3),"Attention","OK"))) | H34: Ouvrir ➜
A35: 10 | B35: ='Athlète 10'!$G$3 -> Athlète 10 | C35: =IFERROR(INDEX('Athlète 10'!$J$6:$J$171,MATCH(TODAY(),'Athlète 10'!$A$6:$A$171,0)),"") -> 0 | D35: =IFERROR(INDEX('Athlète 10'!$K$6:$K$171,MATCH(TODAY(),'Athlète 10'!$A$6:$A$171,0)),"") -> 0 | E35: =IFERROR(INDEX('Athlète 10'!$L$6:$L$171,MATCH(TODAY(),'Athlète 10'!$A$6:$A$171,0)),"") | F35: =IFERROR(INDEX('Athlète 10'!$M$6:$M$171,MATCH(TODAY(),'Athlète 10'!$A$6:$A$171,0)),"") -> 0 | G35: =IF(E35="","",IF(OR(E35<0.5,E35>1.5),"Danger",IF(OR(E35<0.8,E35>1.3),"Attention","OK"))) | H35: Ouvrir ➜
A36: 11 | B36: ='Athlète 11'!$G$3 -> Athlète 11 | C36: =IFERROR(INDEX('Athlète 11'!$J$6:$J$171,MATCH(TODAY(),'Athlète 11'!$A$6:$A$171,0)),"") -> 0 | D36: =IFERROR(INDEX('Athlète 11'!$K$6:$K$171,MATCH(TODAY(),'Athlète 11'!$A$6:$A$171,0)),"") -> 0 | E36: =IFERROR(INDEX('Athlète 11'!$L$6:$L$171,MATCH(TODAY(),'Athlète 11'!$A$6:$A$171,0)),"") | F36: =IFERROR(INDEX('Athlète 11'!$M$6:$M$171,MATCH(TODAY(),'Athlète 11'!$A$6:$A$171,0)),"") -> 0 | G36: =IF(E36="","",IF(OR(E36<0.5,E36>1.5),"Danger",IF(OR(E36<0.8,E36>1.3),"Attention","OK"))) | H36: Ouvrir ➜
A37: 12 | B37: ='Athlète 12'!$G$3 -> Athlète 12 | C37: =IFERROR(INDEX('Athlète 12'!$J$6:$J$171,MATCH(TODAY(),'Athlète 12'!$A$6:$A$171,0)),"") -> 0 | D37: =IFERROR(INDEX('Athlète 12'!$K$6:$K$171,MATCH(TODAY(),'Athlète 12'!$A$6:$A$171,0)),"") -> 0 | E37: =IFERROR(INDEX('Athlète 12'!$L$6:$L$171,MATCH(TODAY(),'Athlète 12'!$A$6:$A$171,0)),"") | F37: =IFERROR(INDEX('Athlète 12'!$M$6:$M$171,MATCH(TODAY(),'Athlète 12'!$A$6:$A$171,0)),"") -> 0 | G37: =IF(E37="","",IF(OR(E37<0.5,E37>1.5),"Danger",IF(OR(E37<0.8,E37>1.3),"Attention","OK"))) | H37: Ouvrir ➜
A38: 13 | B38: ='Athlète 13'!$G$3 -> Athlète 13 | C38: =IFERROR(INDEX('Athlète 13'!$J$6:$J$171,MATCH(TODAY(),'Athlète 13'!$A$6:$A$171,0)),"") -> 0 | D38: =IFERROR(INDEX('Athlète 13'!$K$6:$K$171,MATCH(TODAY(),'Athlète 13'!$A$6:$A$171,0)),"") -> 0 | E38: =IFERROR(INDEX('Athlète 13'!$L$6:$L$171,MATCH(TODAY(),'Athlète 13'!$A$6:$A$171,0)),"") | F38: =IFERROR(INDEX('Athlète 13'!$M$6:$M$171,MATCH(TODAY(),'Athlète 13'!$A$6:$A$171,0)),"") -> 0 | G38: =IF(E38="","",IF(OR(E38<0.5,E38>1.5),"Danger",IF(OR(E38<0.8,E38>1.3),"Attention","OK"))) | H38: Ouvrir ➜
A39: 14 | B39: ='Athlète 14'!$G$3 -> Athlète 14 | C39: =IFERROR(INDEX('Athlète 14'!$J$6:$J$171,MATCH(TODAY(),'Athlète 14'!$A$6:$A$171,0)),"") -> 0 | D39: =IFERROR(INDEX('Athlète 14'!$K$6:$K$171,MATCH(TODAY(),'Athlète 14'!$A$6:$A$171,0)),"") -> 0 | E39: =IFERROR(INDEX('Athlète 14'!$L$6:$L$171,MATCH(TODAY(),'Athlète 14'!$A$6:$A$171,0)),"") | F39: =IFERROR(INDEX('Athlète 14'!$M$6:$M$171,MATCH(TODAY(),'Athlète 14'!$A$6:$A$171,0)),"") -> 0 | G39: =IF(E39="","",IF(OR(E39<0.5,E39>1.5),"Danger",IF(OR(E39<0.8,E39>1.3),"Attention","OK"))) | H39: Ouvrir ➜
A40: 15 | B40: ='Athlète 15'!$G$3 -> Athlète 15 | C40: =IFERROR(INDEX('Athlète 15'!$J$6:$J$171,MATCH(TODAY(),'Athlète 15'!$A$6:$A$171,0)),"") -> 0 | D40: =IFERROR(INDEX('Athlète 15'!$K$6:$K$171,MATCH(TODAY(),'Athlète 15'!$A$6:$A$171,0)),"") -> 0 | E40: =IFERROR(INDEX('Athlète 15'!$L$6:$L$171,MATCH(TODAY(),'Athlète 15'!$A$6:$A$171,0)),"") | F40: =IFERROR(INDEX('Athlète 15'!$M$6:$M$171,MATCH(TODAY(),'Athlète 15'!$A$6:$A$171,0)),"") -> 0 | G40: =IF(E40="","",IF(OR(E40<0.5,E40>1.5),"Danger",IF(OR(E40<0.8,E40>1.3),"Attention","OK"))) | H40: Ouvrir ➜
A41: 16 | B41: ='Athlète 16'!$G$3 -> Athlète 16 | C41: =IFERROR(INDEX('Athlète 16'!$J$6:$J$171,MATCH(TODAY(),'Athlète 16'!$A$6:$A$171,0)),"") -> 0 | D41: =IFERROR(INDEX('Athlète 16'!$K$6:$K$171,MATCH(TODAY(),'Athlète 16'!$A$6:$A$171,0)),"") -> 0 | E41: =IFERROR(INDEX('Athlète 16'!$L$6:$L$171,MATCH(TODAY(),'Athlète 16'!$A$6:$A$171,0)),"") | F41: =IFERROR(INDEX('Athlète 16'!$M$6:$M$171,MATCH(TODAY(),'Athlète 16'!$A$6:$A$171,0)),"") -> 0 | G41: =IF(E41="","",IF(OR(E41<0.5,E41>1.5),"Danger",IF(OR(E41<0.8,E41>1.3),"Attention","OK"))) | H41: Ouvrir ➜
A42: 17 | B42: ='Athlète 17'!$G$3 -> Athlète 17 | C42: =IFERROR(INDEX('Athlète 17'!$J$6:$J$171,MATCH(TODAY(),'Athlète 17'!$A$6:$A$171,0)),"") -> 0 | D42: =IFERROR(INDEX('Athlète 17'!$K$6:$K$171,MATCH(TODAY(),'Athlète 17'!$A$6:$A$171,0)),"") -> 0 | E42: =IFERROR(INDEX('Athlète 17'!$L$6:$L$171,MATCH(TODAY(),'Athlète 17'!$A$6:$A$171,0)),"") | F42: =IFERROR(INDEX('Athlète 17'!$M$6:$M$171,MATCH(TODAY(),'Athlète 17'!$A$6:$A$171,0)),"") -> 0 | G42: =IF(E42="","",IF(OR(E42<0.5,E42>1.5),"Danger",IF(OR(E42<0.8,E42>1.3),"Attention","OK"))) | H42: Ouvrir ➜
A43: 18 | B43: ='Athlète 18'!$G$3 -> Athlète 18 | C43: =IFERROR(INDEX('Athlète 18'!$J$6:$J$171,MATCH(TODAY(),'Athlète 18'!$A$6:$A$171,0)),"") -> 0 | D43: =IFERROR(INDEX('Athlète 18'!$K$6:$K$171,MATCH(TODAY(),'Athlète 18'!$A$6:$A$171,0)),"") -> 0 | E43: =IFERROR(INDEX('Athlète 18'!$L$6:$L$171,MATCH(TODAY(),'Athlète 18'!$A$6:$A$171,0)),"") | F43: =IFERROR(INDEX('Athlète 18'!$M$6:$M$171,MATCH(TODAY(),'Athlète 18'!$A$6:$A$171,0)),"") -> 0 | G43: =IF(E43="","",IF(OR(E43<0.5,E43>1.5),"Danger",IF(OR(E43<0.8,E43>1.3),"Attention","OK"))) | H43: Ouvrir ➜
A44: 19 | B44: ='Athlète 19'!$G$3 -> Athlète 19 | C44: =IFERROR(INDEX('Athlète 19'!$J$6:$J$171,MATCH(TODAY(),'Athlète 19'!$A$6:$A$171,0)),"") -> 0 | D44: =IFERROR(INDEX('Athlète 19'!$K$6:$K$171,MATCH(TODAY(),'Athlète 19'!$A$6:$A$171,0)),"") -> 0 | E44: =IFERROR(INDEX('Athlète 19'!$L$6:$L$171,MATCH(TODAY(),'Athlète 19'!$A$6:$A$171,0)),"") | F44: =IFERROR(INDEX('Athlète 19'!$M$6:$M$171,MATCH(TODAY(),'Athlète 19'!$A$6:$A$171,0)),"") -> 0 | G44: =IF(E44="","",IF(OR(E44<0.5,E44>1.5),"Danger",IF(OR(E44<0.8,E44>1.3),"Attention","OK"))) | H44: Ouvrir ➜
A45: 20 | B45: ='Athlète 20'!$G$3 -> Athlète 20 | C45: =IFERROR(INDEX('Athlète 20'!$J$6:$J$171,MATCH(TODAY(),'Athlète 20'!$A$6:$A$171,0)),"") -> 0 | D45: =IFERROR(INDEX('Athlète 20'!$K$6:$K$171,MATCH(TODAY(),'Athlète 20'!$A$6:$A$171,0)),"") -> 0 | E45: =IFERROR(INDEX('Athlète 20'!$L$6:$L$171,MATCH(TODAY(),'Athlète 20'!$A$6:$A$171,0)),"") | F45: =IFERROR(INDEX('Athlète 20'!$M$6:$M$171,MATCH(TODAY(),'Athlète 20'!$A$6:$A$171,0)),"") -> 0 | G45: =IF(E45="","",IF(OR(E45<0.5,E45>1.5),"Danger",IF(OR(E45<0.8,E45>1.3),"Attention","OK"))) | H45: Ouvrir ➜
A46: 21 | B46: ='Athlète 21'!$G$3 -> Athlète 21 | C46: =IFERROR(INDEX('Athlète 21'!$J$6:$J$171,MATCH(TODAY(),'Athlète 21'!$A$6:$A$171,0)),"") -> 0 | D46: =IFERROR(INDEX('Athlète 21'!$K$6:$K$171,MATCH(TODAY(),'Athlète 21'!$A$6:$A$171,0)),"") -> 0 | E46: =IFERROR(INDEX('Athlète 21'!$L$6:$L$171,MATCH(TODAY(),'Athlète 21'!$A$6:$A$171,0)),"") | F46: =IFERROR(INDEX('Athlète 21'!$M$6:$M$171,MATCH(TODAY(),'Athlète 21'!$A$6:$A$171,0)),"") -> 0 | G46: =IF(E46="","",IF(OR(E46<0.5,E46>1.5),"Danger",IF(OR(E46<0.8,E46>1.3),"Attention","OK"))) | H46: Ouvrir ➜
A47: 22 | B47: ='Athlète 22'!$G$3 -> Athlète 22 | C47: =IFERROR(INDEX('Athlète 22'!$J$6:$J$171,MATCH(TODAY(),'Athlète 22'!$A$6:$A$171,0)),"") -> 0 | D47: =IFERROR(INDEX('Athlète 22'!$K$6:$K$171,MATCH(TODAY(),'Athlète 22'!$A$6:$A$171,0)),"") -> 0 | E47: =IFERROR(INDEX('Athlète 22'!$L$6:$L$171,MATCH(TODAY(),'Athlète 22'!$A$6:$A$171,0)),"") | F47: =IFERROR(INDEX('Athlète 22'!$M$6:$M$171,MATCH(TODAY(),'Athlète 22'!$A$6:$A$171,0)),"") -> 0 | G47: =IF(E47="","",IF(OR(E47<0.5,E47>1.5),"Danger",IF(OR(E47<0.8,E47>1.3),"Attention","OK"))) | H47: Ouvrir ➜
A48: 23 | B48: ='Athlète 23'!$G$3 -> Athlète 23 | C48: =IFERROR(INDEX('Athlète 23'!$J$6:$J$171,MATCH(TODAY(),'Athlète 23'!$A$6:$A$171,0)),"") -> 0 | D48: =IFERROR(INDEX('Athlète 23'!$K$6:$K$171,MATCH(TODAY(),'Athlète 23'!$A$6:$A$171,0)),"") -> 0 | E48: =IFERROR(INDEX('Athlète 23'!$L$6:$L$171,MATCH(TODAY(),'Athlète 23'!$A$6:$A$171,0)),"") | F48: =IFERROR(INDEX('Athlète 23'!$M$6:$M$171,MATCH(TODAY(),'Athlète 23'!$A$6:$A$171,0)),"") -> 0 | G48: =IF(E48="","",IF(OR(E48<0.5,E48>1.5),"Danger",IF(OR(E48<0.8,E48>1.3),"Attention","OK"))) | H48: Ouvrir ➜
A49: 24 | B49: ='Athlète 24'!$G$3 -> Athlète 24 | C49: =IFERROR(INDEX('Athlète 24'!$J$6:$J$171,MATCH(TODAY(),'Athlète 24'!$A$6:$A$171,0)),"") -> 0 | D49: =IFERROR(INDEX('Athlète 24'!$K$6:$K$171,MATCH(TODAY(),'Athlète 24'!$A$6:$A$171,0)),"") -> 0 | E49: =IFERROR(INDEX('Athlète 24'!$L$6:$L$171,MATCH(TODAY(),'Athlète 24'!$A$6:$A$171,0)),"") | F49: =IFERROR(INDEX('Athlète 24'!$M$6:$M$171,MATCH(TODAY(),'Athlète 24'!$A$6:$A$171,0)),"") -> 0 | G49: =IF(E49="","",IF(OR(E49<0.5,E49>1.5),"Danger",IF(OR(E49<0.8,E49>1.3),"Attention","OK"))) | H49: Ouvrir ➜
A50: 25 | B50: ='Athlète 25'!$G$3 -> Athlète 25 | C50: =IFERROR(INDEX('Athlète 25'!$J$6:$J$171,MATCH(TODAY(),'Athlète 25'!$A$6:$A$171,0)),"") -> 0 | D50: =IFERROR(INDEX('Athlète 25'!$K$6:$K$171,MATCH(TODAY(),'Athlète 25'!$A$6:$A$171,0)),"") -> 0 | E50: =IFERROR(INDEX('Athlète 25'!$L$6:$L$171,MATCH(TODAY(),'Athlète 25'!$A$6:$A$171,0)),"") | F50: =IFERROR(INDEX('Athlète 25'!$M$6:$M$171,MATCH(TODAY(),'Athlète 25'!$A$6:$A$171,0)),"") -> 0 | G50: =IF(E50="","",IF(OR(E50<0.5,E50>1.5),"Danger",IF(OR(E50<0.8,E50>1.3),"Attention","OK"))) | H50: Ouvrir ➜
A51: 26 | B51: ='Athlète 26'!$G$3 -> Athlète 26 | C51: =IFERROR(INDEX('Athlète 26'!$J$6:$J$171,MATCH(TODAY(),'Athlète 26'!$A$6:$A$171,0)),"") -> 0 | D51: =IFERROR(INDEX('Athlète 26'!$K$6:$K$171,MATCH(TODAY(),'Athlète 26'!$A$6:$A$171,0)),"") -> 0 | E51: =IFERROR(INDEX('Athlète 26'!$L$6:$L$171,MATCH(TODAY(),'Athlète 26'!$A$6:$A$171,0)),"") | F51: =IFERROR(INDEX('Athlète 26'!$M$6:$M$171,MATCH(TODAY(),'Athlète 26'!$A$6:$A$171,0)),"") -> 0 | G51: =IF(E51="","",IF(OR(E51<0.5,E51>1.5),"Danger",IF(OR(E51<0.8,E51>1.3),"Attention","OK"))) | H51: Ouvrir ➜
A52: 27 | B52: ='Athlète 27'!$G$3 -> Athlète 27 | C52: =IFERROR(INDEX('Athlète 27'!$J$6:$J$171,MATCH(TODAY(),'Athlète 27'!$A$6:$A$171,0)),"") -> 0 | D52: =IFERROR(INDEX('Athlète 27'!$K$6:$K$171,MATCH(TODAY(),'Athlète 27'!$A$6:$A$171,0)),"") -> 0 | E52: =IFERROR(INDEX('Athlète 27'!$L$6:$L$171,MATCH(TODAY(),'Athlète 27'!$A$6:$A$171,0)),"") | F52: =IFERROR(INDEX('Athlète 27'!$M$6:$M$171,MATCH(TODAY(),'Athlète 27'!$A$6:$A$171,0)),"") -> 0 | G52: =IF(E52="","",IF(OR(E52<0.5,E52>1.5),"Danger",IF(OR(E52<0.8,E52>1.3),"Attention","OK"))) | H52: Ouvrir ➜
A53: 28 | B53: ='Athlète 28'!$G$3 -> Athlète 28 | C53: =IFERROR(INDEX('Athlète 28'!$J$6:$J$171,MATCH(TODAY(),'Athlète 28'!$A$6:$A$171,0)),"") -> 0 | D53: =IFERROR(INDEX('Athlète 28'!$K$6:$K$171,MATCH(TODAY(),'Athlète 28'!$A$6:$A$171,0)),"") -> 0 | E53: =IFERROR(INDEX('Athlète 28'!$L$6:$L$171,MATCH(TODAY(),'Athlète 28'!$A$6:$A$171,0)),"") | F53: =IFERROR(INDEX('Athlète 28'!$M$6:$M$171,MATCH(TODAY(),'Athlète 28'!$A$6:$A$171,0)),"") -> 0 | G53: =IF(E53="","",IF(OR(E53<0.5,E53>1.5),"Danger",IF(OR(E53<0.8,E53>1.3),"Attention","OK"))) | H53: Ouvrir ➜
A54: 29 | B54: ='Athlète 29'!$G$3 -> Athlète 29 | C54: =IFERROR(INDEX('Athlète 29'!$J$6:$J$171,MATCH(TODAY(),'Athlète 29'!$A$6:$A$171,0)),"") -> 0 | D54: =IFERROR(INDEX('Athlète 29'!$K$6:$K$171,MATCH(TODAY(),'Athlète 29'!$A$6:$A$171,0)),"") -> 0 | E54: =IFERROR(INDEX('Athlète 29'!$L$6:$L$171,MATCH(TODAY(),'Athlète 29'!$A$6:$A$171,0)),"") | F54: =IFERROR(INDEX('Athlète 29'!$M$6:$M$171,MATCH(TODAY(),'Athlète 29'!$A$6:$A$171,0)),"") -> 0 | G54: =IF(E54="","",IF(OR(E54<0.5,E54>1.5),"Danger",IF(OR(E54<0.8,E54>1.3),"Attention","OK"))) | H54: Ouvrir ➜
A55: 30 | B55: ='Athlète 30'!$G$3 -> Athlète 30 | C55: =IFERROR(INDEX('Athlète 30'!$J$6:$J$171,MATCH(TODAY(),'Athlète 30'!$A$6:$A$171,0)),"") -> 0 | D55: =IFERROR(INDEX('Athlète 30'!$K$6:$K$171,MATCH(TODAY(),'Athlète 30'!$A$6:$A$171,0)),"") -> 0 | E55: =IFERROR(INDEX('Athlète 30'!$L$6:$L$171,MATCH(TODAY(),'Athlète 30'!$A$6:$A$171,0)),"") | F55: =IFERROR(INDEX('Athlète 30'!$M$6:$M$171,MATCH(TODAY(),'Athlète 30'!$A$6:$A$171,0)),"") -> 0 | G55: =IF(E55="","",IF(OR(E55<0.5,E55>1.5),"Danger",IF(OR(E55<0.8,E55>1.3),"Attention","OK"))) | H55: Ouvrir ➜

Sheet Paramètres
A1: PARAMÈTRES DE L'OUTIL
A3: Paramètre | B3: Valeur | C3: Commentaire
A4: Nombre d'athlètes | B4: 30 | C4: Nombre de fiches Athlète générées dans ce classeur.
A5: Date de début de saison | B5: 46222 | C5: Aujourd'hui à la génération du fichier.
A6: Date de fin de saison | B6: 46387 | C6: 31 décembre 2026.
A7: Fenêtre charge aiguë (jours) | B7: 7 | C7: Somme des CT sur 7 jours glissants.
A8: Fenêtre charge chronique (jours) | B8: 28 | C8: Moyenne des CT sur 28 jours glissants.
A9: Seuil ACWR vert - bas | B9: 0.8
A10: Seuil ACWR vert - haut | B10: 1.3
A11: Seuil ACWR orange - bas | B11: 0.5
A12: Seuil ACWR orange - haut | B12: 1.5
A15: Faire évoluer le nombre d'athlètes (20 / 30 / 40 / 50)
A16: Ce classeur est généré par un script Python (fourni séparément). Pour passer à 20, 40 ou 50 athlètes, relancer le script avec le paramètre souhaité : toutes les fiches, formules, graphiques, validations et le Dashboard sont reconstruits automatiquement, sans aucune formule à retoucher à la main.
A21: Légende des couleurs ACWR
A23: ⚠ Remarque méthodologique : conformément au cahier des charges, la Charge aiguë est une SOMME sur 7 jours alors que la Charge chronique est une MOYENNE sur 28 jours. L'ACWR obtenu (somme/moyenne) est donc environ 7x plus élevé que l'ACWR classique de la littérature sportive (moyenne/moyenne). Les seuils 0.8/1.3/1.5 ont été conservés tels que demandés. Pour un ACWR 'classique', modifier la formule de Charge aiguë en AVERAGE(...) au lieu de SUM(...).
A27: Vert | B27: 0.8 ≤ ACWR ≤ 1.3
A28: Orange | B28: 0.5 ≤ ACWR < 0.8 ou 1.3 < ACWR ≤ 1.5
A29: Rouge | B29: ACWR < 0.5 ou ACWR > 1.5

Sheet Listes
A1: Type de séance | C1: Seuils ACWR
A2: Repos | C2: Rouge bas | D2: 0 | E2: 0.5
A3: Match | C3: Orange bas | D3: 0.5 | E3: 0.8
A4: Match amical | C4: Vert | D4: 0.8 | E4: 1.3
A5: Technique | C5: Orange haut | D5: 1.3 | E5: 1.5
A6: Tactique | C6: Rouge haut | D6: 1.5 | E6: 99
A7: Renforcement
A8: Force
A9: Puissance
A10: Explosivité
A11: Vitesse
A12: VMA
A13: HIIT
A14: Endurance
A15: Récupération
A16: Mobilité
A17: Prévention
A18: Réathlétisation
A19: Autre

Sheet Base de données
A1: BASE DE DONNÉES - MOYENNES QUOTIDIENNES DU GROUPE
A3: Date | B3: CT moyenne du groupe | C3: Fatigue moyenne du groupe | D3: ACWR moyen du groupe
A4: ='Athlète 1'!A6 -> 46222 | B4: =AVERAGE('Athlète 1'!I6,'Athlète 2'!I6,'Athlète 3'!I6,'Athlète 4'!I6,'Athlète 5'!I6,'Athlète 6'!I6,'Athlète 7'!I6,'Athlète 8'!I6,'Athlète 9'!I6,'Athlète 10'!I6,'Athlète 11'!I6,'Athlète 12'!I6,'Athlète 13'!I6,'Athlète 14'!I6,'Athlète 15'!I6,'Athlète 16'!I6,'Athlète 17'!I6,'Athlète 18'!I6,'Athlète 19'!I6,'Athlète 20'!I6,'Athlète 21'!I6,'Athlète 22'!I6,'Athlète 23'!I6,'Athlète 24'!I6,'Athlète 25'!I6,'Athlète 26'!I6,'Athlète 27'!I6,'Athlète 28'!I6,'Athlète 29'!I6,'Athlète 30'!I6) -> 0 | C4: =AVERAGE('Athlète 1'!M6,'Athlète 2'!M6,'Athlète 3'!M6,'Athlète 4'!M6,'Athlète 5'!M6,'Athlète 6'!M6,'Athlète 7'!M6,'Athlète 8'!M6,'Athlète 9'!M6,'Athlète 10'!M6,'Athlète 11'!M6,'Athlète 12'!M6,'Athlète 13'!M6,'Athlète 14'!M6,'Athlète 15'!M6,'Athlète 16'!M6,'Athlète 17'!M6,'Athlète 18'!M6,'Athlète 19'!M6,'Athlète 20'!M6,'Athlète 21'!M6,'Athlète 22'!M6,'Athlète 23'!M6,'Athlète 24'!M6,'Athlète 25'!M6,'Athlète 26'!M6,'Athlète 27'!M6,'Athlète 28'!M6,'Athlète 29'!M6,'Athlète 30'!M6) -> 0 | D4: =IFERROR(AVERAGE('Athlète 1'!L6,'Athlète 2'!L6,'Athlète 3'!L6,'Athlète 4'!L6,'Athlète 5'!L6,'Athlète 6'!L6,'Athlète 7'!L6,'Athlète 8'!L6,'Athlète 9'!L6,'Athlète 10'!L6,'Athlète 11'!L6,'Athlète 12'!L6,'Athlète 13'!L6,'Athlète 14'!L6,'Athlète 15'!L6,'Athlète 16'!L6,'Athlète 17'!L6,'Athlète 18'!L6,'Athlète 19'!L6,'Athlète 20'!L6,'Athlète 21'!L6,'Athlète 22'!L6,'Athlète 23'!L6,'Athlète 24'!L6,'Athlète 25'!L6,'Athlète 26'!L6,'Athlète 27'!L6,'Athlète 28'!L6,'Athlète 29'!L6,'Athlète 30'!L6),"")
A5: ='Athlète 1'!A7 -> 46223 | B5: =AVERAGE('Athlète 1'!I7,'Athlète 2'!I7,'Athlète 3'!I7,'Athlète 4'!I7,'Athlète 5'!I7,'Athlète 6'!I7,'Athlète 7'!I7,'Athlète 8'!I7,'Athlète 9'!I7,'Athlète 10'!I7,'Athlète 11'!I7,'Athlète 12'!I7,'Athlète 13'!I7,'Athlète 14'!I7,'Athlète 15'!I7,'Athlète 16'!I7,'Athlète 17'!I7,'Athlète 18'!I7,'Athlète 19'!I7,'Athlète 20'!I7,'Athlète 21'!I7,'Athlète 22'!I7,'Athlète 23'!I7,'Athlète 24'!I7,'Athlète 25'!I7,'Athlète 26'!I7,'Athlète 27'!I7,'Athlète 28'!I7,'Athlète 29'!I7,'Athlète 30'!I7) -> 0 | C5: =AVERAGE('Athlète 1'!M7,'Athlète 2'!M7,'Athlète 3'!M7,'Athlète 4'!M7,'Athlète 5'!M7,'Athlète 6'!M7,'Athlète 7'!M7,'Athlète 8'!M7,'Athlète 9'!M7,'Athlète 10'!M7,'Athlète 11'!M7,'Athlète 12'!M7,'Athlète 13'!M7,'Athlète 14'!M7,'Athlète 15'!M7,'Athlète 16'!M7,'Athlète 17'!M7,'Athlète 18'!M7,'Athlète 19'!M7,'Athlète 20'!M7,'Athlète 21'!M7,'Athlète 22'!M7,'Athlète 23'!M7,'Athlète 24'!M7,'Athlète 25'!M7,'Athlète 26'!M7,'Athlète 27'!M7,'Athlète 28'!M7,'Athlète 29'!M7,'Athlète 30'!M7) -> 0 | D5: =IFERROR(AVERAGE('Athlète 1'!L7,'Athlète 2'!L7,'Athlète 3'!L7,'Athlète 4'!L7,'Athlète 5'!L7,'Athlète 6'!L7,'Athlète 7'!L7,'Athlète 8'!L7,'Athlète 9'!L7,'Athlète 10'!L7,'Athlète 11'!L7,'Athlète 12'!L7,'Athlète 13'!L7,'Athlète 14'!L7,'Athlète 15'!L7,'Athlète 16'!L7,'Athlète 17'!L7,'Athlète 18'!L7,'Athlète 19'!L7,'Athlète 20'!L7,'Athlète 21'!L7,'Athlète 22'!L7,'Athlète 23'!L7,'Athlète 24'!L7,'Athlète 25'!L7,'Athlète 26'!L7,'Athlète 27'!L7,'Athlète 28'!L7,'Athlète 29'!L7,'Athlète 30'!L7),"")
A6: ='Athlète 1'!A8 -> 46224 | B6: =AVERAGE('Athlète 1'!I8,'Athlète 2'!I8,'Athlète 3'!I8,'Athlète 4'!I8,'Athlète 5'!I8,'Athlète 6'!I8,'Athlète 7'!I8,'Athlète 8'!I8,'Athlète 9'!I8,'Athlète 10'!I8,'Athlète 11'!I8,'Athlète 12'!I8,'Athlète 13'!I8,'Athlète 14'!I8,'Athlète 15'!I8,'Athlète 16'!I8,'Athlète 17'!I8,'Athlète 18'!I8,'Athlète 19'!I8,'Athlète 20'!I8,'Athlète 21'!I8,'Athlète 22'!I8,'Athlète 23'!I8,'Athlète 24'!I8,'Athlète 25'!I8,'Athlète 26'!I8,'Athlète 27'!I8,'Athlète 28'!I8,'Athlète 29'!I8,'Athlète 30'!I8) -> 0 | C6: =AVERAGE('Athlète 1'!M8,'Athlète 2'!M8,'Athlète 3'!M8,'Athlète 4'!M8,'Athlète 5'!M8,'Athlète 6'!M8,'Athlète 7'!M8,'Athlète 8'!M8,'Athlète 9'!M8,'Athlète 10'!M8,'Athlète 11'!M8,'Athlète 12'!M8,'Athlète 13'!M8,'Athlète 14'!M8,'Athlète 15'!M8,'Athlète 16'!M8,'Athlète 17'!M8,'Athlète 18'!M8,'Athlète 19'!M8,'Athlète 20'!M8,'Athlète 21'!M8,'Athlète 22'!M8,'Athlète 23'!M8,'Athlète 24'!M8,'Athlète 25'!M8,'Athlète 26'!M8,'Athlète 27'!M8,'Athlète 28'!M8,'Athlète 29'!M8,'Athlète 30'!M8) -> 0 | D6: =IFERROR(AVERAGE('Athlète 1'!L8,'Athlète 2'!L8,'Athlète 3'!L8,'Athlète 4'!L8,'Athlète 5'!L8,'Athlète 6'!L8,'Athlète 7'!L8,'Athlète 8'!L8,'Athlète 9'!L8,'Athlète 10'!L8,'Athlète 11'!L8,'Athlète 12'!L8,'Athlète 13'!L8,'Athlète 14'!L8,'Athlète 15'!L8,'Athlète 16'!L8,'Athlète 17'!L8,'Athlète 18'!L8,'Athlète 19'!L8,'Athlète 20'!L8,'Athlète 21'!L8,'Athlète 22'!L8,'Athlète 23'!L8,'Athlète 24'!L8,'Athlète 25'!L8,'Athlète 26'!L8,'Athlète 27'!L8,'Athlète 28'!L8,'Athlète 29'!L8,'Athlète 30'!L8),"")
A7: ='Athlète 1'!A9 -> 46225 | B7: =AVERAGE('Athlète 1'!I9,'Athlète 2'!I9,'Athlète 3'!I9,'Athlète 4'!I9,'Athlète 5'!I9,'Athlète 6'!I9,'Athlète 7'!I9,'Athlète 8'!I9,'Athlète 9'!I9,'Athlète 10'!I9,'Athlète 11'!I9,'Athlète 12'!I9,'Athlète 13'!I9,'Athlète 14'!I9,'Athlète 15'!I9,'Athlète 16'!I9,'Athlète 17'!I9,'Athlète 18'!I9,'Athlète 19'!I9,'Athlète 20'!I9,'Athlète 21'!I9,'Athlète 22'!I9,'Athlète 23'!I9,'Athlète 24'!I9,'Athlète 25'!I9,'Athlète 26'!I9,'Athlète 27'!I9,'Athlète 28'!I9,'Athlète 29'!I9,'Athlète 30'!I9) -> 0 | C7: =AVERAGE('Athlète 1'!M9,'Athlète 2'!M9,'Athlète 3'!M9,'Athlète 4'!M9,'Athlète 5'!M9,'Athlète 6'!M9,'Athlète 7'!M9,'Athlète 8'!M9,'Athlète 9'!M9,'Athlète 10'!M9,'Athlète 11'!M9,'Athlète 12'!M9,'Athlète 13'!M9,'Athlète 14'!M9,'Athlète 15'!M9,'Athlète 16'!M9,'Athlète 17'!M9,'Athlète 18'!M9,'Athlète 19'!M9,'Athlète 20'!M9,'Athlète 21'!M9,'Athlète 22'!M9,'Athlète 23'!M9,'Athlète 24'!M9,'Athlète 25'!M9,'Athlète 26'!M9,'Athlète 27'!M9,'Athlète 28'!M9,'Athlète 29'!M9,'Athlète 30'!M9) -> 0 | D7: =IFERROR(AVERAGE('Athlète 1'!L9,'Athlète 2'!L9,'Athlète 3'!L9,'Athlète 4'!L9,'Athlète 5'!L9,'Athlète 6'!L9,'Athlète 7'!L9,'Athlète 8'!L9,'Athlète 9'!L9,'Athlète 10'!L9,'Athlète 11'!L9,'Athlète 12'!L9,'Athlète 13'!L9,'Athlète 14'!L9,'Athlète 15'!L9,'Athlète 16'!L9,'Athlète 17'!L9,'Athlète 18'!L9,'Athlète 19'!L9,'Athlète 20'!L9,'Athlète 21'!L9,'Athlète 22'!L9,'Athlète 23'!L9,'Athlète 24'!L9,'Athlète 25'!L9,'Athlète 26'!L9,'Athlète 27'!L9,'Athlète 28'!L9,'Athlète 29'!L9,'Athlète 30'!L9),"")
A8: ='Athlète 1'!A10 -> 46226 | B8: =AVERAGE('Athlète 1'!I10,'Athlète 2'!I10,'Athlète 3'!I10,'Athlète 4'!I10,'Athlète 5'!I10,'Athlète 6'!I10,'Athlète 7'!I10,'Athlète 8'!I10,'Athlète 9'!I10,'Athlète 10'!I10,'Athlète 11'!I10,'Athlète 12'!I10,'Athlète 13'!I10,'Athlète 14'!I10,'Athlète 15'!I10,'Athlète 16'!I10,'Athlète 17'!I10,'Athlète 18'!I10,'Athlète 19'!I10,'Athlète 20'!I10,'Athlète 21'!I10,'Athlète 22'!I10,'Athlète 23'!I10,'Athlète 24'!I10,'Athlète 25'!I10,'Athlète 26'!I10,'Athlète 27'!I10,'Athlète 28'!I10,'Athlète 29'!I10,'Athlète 30'!I10) -> 0 | C8: =AVERAGE('Athlète 1'!M10,'Athlète 2'!M10,'Athlète 3'!M10,'Athlète 4'!M10,'Athlète 5'!M10,'Athlète 6'!M10,'Athlète 7'!M10,'Athlète 8'!M10,'Athlète 9'!M10,'Athlète 10'!M10,'Athlète 11'!M10,'Athlète 12'!M10,'Athlète 13'!M10,'Athlète 14'!M10,'Athlète 15'!M10,'Athlète 16'!M10,'Athlète 17'!M10,'Athlète 18'!M10,'Athlète 19'!M10,'Athlète 20'!M10,'Athlète 21'!M10,'Athlète 22'!M10,'Athlète 23'!M10,'Athlète 24'!M10,'Athlète 25'!M10,'Athlète 26'!M10,'Athlète 27'!M10,'Athlète 28'!M10,'Athlète 29'!M10,'Athlète 30'!M10) -> 0 | D8: =IFERROR(AVERAGE('Athlète 1'!L10,'Athlète 2'!L10,'Athlète 3'!L10,'Athlète 4'!L10,'Athlète 5'!L10,'Athlète 6'!L10,'Athlète 7'!L10,'Athlète 8'!L10,'Athlète 9'!L10,'Athlète 10'!L10,'Athlète 11'!L10,'Athlète 12'!L10,'Athlète 13'!L10,'Athlète 14'!L10,'Athlète 15'!L10,'Athlète 16'!L10,'Athlète 17'!L10,'Athlète 18'!L10,'Athlète 19'!L10,'Athlète 20'!L10,'Athlète 21'!L10,'Athlète 22'!L10,'Athlète 23'!L10,'Athlète 24'!L10,'Athlète 25'!L10,'Athlète 26'!L10,'Athlète 27'!L10,'Athlète 28'!L10,'Athlète 29'!L10,'Athlète 30'!L10),"")
A9: ='Athlète 1'!A11 -> 46227 | B9: =AVERAGE('Athlète 1'!I11,'Athlète 2'!I11,'Athlète 3'!I11,'Athlète 4'!I11,'Athlète 5'!I11,'Athlète 6'!I11,'Athlète 7'!I11,'Athlète 8'!I11,'Athlète 9'!I11,'Athlète 10'!I11,'Athlète 11'!I11,'Athlète 12'!I11,'Athlète 13'!I11,'Athlète 14'!I11,'Athlète 15'!I11,'Athlète 16'!I11,'Athlète 17'!I11,'Athlète 18'!I11,'Athlète 19'!I11,'Athlète 20'!I11,'Athlète 21'!I11,'Athlète 22'!I11,'Athlète 23'!I11,'Athlète 24'!I11,'Athlète 25'!I11,'Athlète 26'!I11,'Athlète 27'!I11,'Athlète 28'!I11,'Athlète 29'!I11,'Athlète 30'!I11) -> 0 | C9: =AVERAGE('Athlète 1'!M11,'Athlète 2'!M11,'Athlète 3'!M11,'Athlète 4'!M11,'Athlète 5'!M11,'Athlète 6'!M11,'Athlète 7'!M11,'Athlète 8'!M11,'Athlète 9'!M11,'Athlète 10'!M11,'Athlète 11'!M11,'Athlète 12'!M11,'Athlète 13'!M11,'Athlète 14'!M11,'Athlète 15'!M11,'Athlète 16'!M11,'Athlète 17'!M11,'Athlète 18'!M11,'Athlète 19'!M11,'Athlète 20'!M11,'Athlète 21'!M11,'Athlète 22'!M11,'Athlète 23'!M11,'Athlète 24'!M11,'Athlète 25'!M11,'Athlète 26'!M11,'Athlète 27'!M11,'Athlète 28'!M11,'Athlète 29'!M11,'Athlète 30'!M11) -> 0 | D9: =IFERROR(AVERAGE('Athlète 1'!L11,'Athlète 2'!L11,'Athlète 3'!L11,'Athlète 4'!L11,'Athlète 5'!L11,'Athlète 6'!L11,'Athlète 7'!L11,'Athlète 8'!L11,'Athlète 9'!L11,'Athlète 10'!L11,'Athlète 11'!L11,'Athlète 12'!L11,'Athlète 13'!L11,'Athlète 14'!L11,'Athlète 15'!L11,'Athlète 16'!L11,'Athlète 17'!L11,'Athlète 18'!L11,'Athlète 19'!L11,'Athlète 20'!L11,'Athlète 21'!L11,'Athlète 22'!L11,'Athlète 23'!L11,'Athlète 24'!L11,'Athlète 25'!L11,'Athlète 26'!L11,'Athlète 27'!L11,'Athlète 28'!L11,'Athlète 29'!L11,'Athlète 30'!L11),"")
A10: ='Athlète 1'!A12 -> 46228 | B10: =AVERAGE('Athlète 1'!I12,'Athlète 2'!I12,'Athlète 3'!I12,'Athlète 4'!I12,'Athlète 5'!I12,'Athlète 6'!I12,'Athlète 7'!I12,'Athlète 8'!I12,'Athlète 9'!I12,'Athlète 10'!I12,'Athlète 11'!I12,'Athlète 12'!I12,'Athlète 13'!I12,'Athlète 14'!I12,'Athlète 15'!I12,'Athlète 16'!I12,'Athlète 17'!I12,'Athlète 18'!I12,'Athlète 19'!I12,'Athlète 20'!I12,'Athlète 21'!I12,'Athlète 22'!I12,'Athlète 23'!I12,'Athlète 24'!I12,'Athlète 25'!I12,'Athlète 26'!I12,'Athlète 27'!I12,'Athlète 28'!I12,'Athlète 29'!I12,'Athlète 30'!I12) -> 0 | C10: =AVERAGE('Athlète 1'!M12,'Athlète 2'!M12,'Athlète 3'!M12,'Athlète 4'!M12,'Athlète 5'!M12,'Athlète 6'!M12,'Athlète 7'!M12,'Athlète 8'!M12,'Athlète 9'!M12,'Athlète 10'!M12,'Athlète 11'!M12,'Athlète 12'!M12,'Athlète 13'!M12,'Athlète 14'!M12,'Athlète 15'!M12,'Athlète 16'!M12,'Athlète 17'!M12,'Athlète 18'!M12,'Athlète 19'!M12,'Athlète 20'!M12,'Athlète 21'!M12,'Athlète 22'!M12,'Athlète 23'!M12,'Athlète 24'!M12,'Athlète 25'!M12,'Athlète 26'!M12,'Athlète 27'!M12,'Athlète 28'!M12,'Athlète 29'!M12,'Athlète 30'!M12) -> 0 | D10: =IFERROR(AVERAGE('Athlète 1'!L12,'Athlète 2'!L12,'Athlète 3'!L12,'Athlète 4'!L12,'Athlète 5'!L12,'Athlète 6'!L12,'Athlète 7'!L12,'Athlète 8'!L12,'Athlète 9'!L12,'Athlète 10'!L12,'Athlète 11'!L12,'Athlète 12'!L12,'Athlète 13'!L12,'Athlète 14'!L12,'Athlète 15'!L12,'Athlète 16'!L12,'Athlète 17'!L12,'Athlète 18'!L12,'Athlète 19'!L12,'Athlète 20'!L12,'Athlète 21'!L12,'Athlète 22'!L12,'Athlète 23'!L12,'Athlète 24'!L12,'Athlète 25'!L12,'Athlète 26'!L12,'Athlète 27'!L12,'Athlète 28'!L12,'Athlète 29'!L12,'Athlète 30'!L12),"")
A11: ='Athlète 1'!A13 -> 46229 | B11: =AVERAGE('Athlète 1'!I13,'Athlète 2'!I13,'Athlète 3'!I13,'Athlète 4'!I13,'Athlète 5'!I13,'Athlète 6'!I13,'Athlète 7'!I13,'Athlète 8'!I13,'Athlète 9'!I13,'Athlète 10'!I13,'Athlète 11'!I13,'Athlète 12'!I13,'Athlète 13'!I13,'Athlète 14'!I13,'Athlète 15'!I13,'Athlète 16'!I13,'Athlète 17'!I13,'Athlète 18'!I13,'Athlète 19'!I13,'Athlète 20'!I13,'Athlète 21'!I13,'Athlète 22'!I13,'Athlète 23'!I13,'Athlète 24'!I13,'Athlète 25'!I13,'Athlète 26'!I13,'Athlète 27'!I13,'Athlète 28'!I13,'Athlète 29'!I13,'Athlète 30'!I13) -> 0 | C11: =AVERAGE('Athlète 1'!M13,'Athlète 2'!M13,'Athlète 3'!M13,'Athlète 4'!M13,'Athlète 5'!M13,'Athlète 6'!M13,'Athlète 7'!M13,'Athlète 8'!M13,'Athlète 9'!M13,'Athlète 10'!M13,'Athlète 11'!M13,'Athlète 12'!M13,'Athlète 13'!M13,'Athlète 14'!M13,'Athlète 15'!M13,'Athlète 16'!M13,'Athlète 17'!M13,'Athlète 18'!M13,'Athlète 19'!M13,'Athlète 20'!M13,'Athlète 21'!M13,'Athlète 22'!M13,'Athlète 23'!M13,'Athlète 24'!M13,'Athlète 25'!M13,'Athlète 26'!M13,'Athlète 27'!M13,'Athlète 28'!M13,'Athlète 29'!M13,'Athlète 30'!M13) -> 0 | D11: =IFERROR(AVERAGE('Athlète 1'!L13,'Athlète 2'!L13,'Athlète 3'!L13,'Athlète 4'!L13,'Athlète 5'!L13,'Athlète 6'!L13,'Athlète 7'!L13,'Athlète 8'!L13,'Athlète 9'!L13,'Athlète 10'!L13,'Athlète 11'!L13,'Athlète 12'!L13,'Athlète 13'!L13,'Athlète 14'!L13,'Athlète 15'!L13,'Athlète 16'!L13,'Athlète 17'!L13,'Athlète 18'!L13,'Athlète 19'!L13,'Athlète 20'!L13,'Athlète 21'!L13,'Athlète 22'!L13,'Athlète 23'!L13,'Athlète 24'!L13,'Athlète 25'!L13,'Athlète 26'!L13,'Athlète 27'!L13,'Athlète 28'!L13,'Athlète 29'!L13,'Athlète 30'!L13),"")
A12: ='Athlète 1'!A14 -> 46230 | B12: =AVERAGE('Athlète 1'!I14,'Athlète 2'!I14,'Athlète 3'!I14,'Athlète 4'!I14,'Athlète 5'!I14,'Athlète 6'!I14,'Athlète 7'!I14,'Athlète 8'!I14,'Athlète 9'!I14,'Athlète 10'!I14,'Athlète 11'!I14,'Athlète 12'!I14,'Athlète 13'!I14,'Athlète 14'!I14,'Athlète 15'!I14,'Athlète 16'!I14,'Athlète 17'!I14,'Athlète 18'!I14,'Athlète 19'!I14,'Athlète 20'!I14,'Athlète 21'!I14,'Athlète 22'!I14,'Athlète 23'!I14,'Athlète 24'!I14,'Athlète 25'!I14,'Athlète 26'!I14,'Athlète 27'!I14,'Athlète 28'!I14,'Athlète 29'!I14,'Athlète 30'!I14) -> 0 | C12: =AVERAGE('Athlète 1'!M14,'Athlète 2'!M14,'Athlète 3'!M14,'Athlète 4'!M14,'Athlète 5'!M14,'Athlète 6'!M14,'Athlète 7'!M14,'Athlète 8'!M14,'Athlète 9'!M14,'Athlète 10'!M14,'Athlète 11'!M14,'Athlète 12'!M14,'Athlète 13'!M14,'Athlète 14'!M14,'Athlète 15'!M14,'Athlète 16'!M14,'Athlète 17'!M14,'Athlète 18'!M14,'Athlète 19'!M14,'Athlète 20'!M14,'Athlète 21'!M14,'Athlète 22'!M14,'Athlète 23'!M14,'Athlète 24'!M14,'Athlète 25'!M14,'Athlète 26'!M14,'Athlète 27'!M14,'Athlète 28'!M14,'Athlète 29'!M14,'Athlète 30'!M14) -> 0 | D12: =IFERROR(AVERAGE('Athlète 1'!L14,'Athlète 2'!L14,'Athlète 3'!L14,'Athlète 4'!L14,'Athlète 5'!L14,'Athlète 6'!L14,'Athlète 7'!L14,'Athlète 8'!L14,'Athlète 9'!L14,'Athlète 10'!L14,'Athlète 11'!L14,'Athlète 12'!L14,'Athlète 13'!L14,'Athlète 14'!L14,'Athlète 15'!L14,'Athlète 16'!L14,'Athlète 17'!L14,'Athlète 18'!L14,'Athlète 19'!L14,'Athlète 20'!L14,'Athlète 21'!L14,'Athlète 22'!L14,'Athlète 23'!L14,'Athlète 24'!L14,'Athlète 25'!L14,'Athlète 26'!L14,'Athlète 27'!L14,'Athlète 28'!L14,'Athlète 29'!L14,'Athlète 30'!L14),"")
A13: ='Athlète 1'!A15 -> 46231 | B13: =AVERAGE('Athlète 1'!I15,'Athlète 2'!I15,'Athlète 3'!I15,'Athlète 4'!I15,'Athlète 5'!I15,'Athlète 6'!I15,'Athlète 7'!I15,'Athlète 8'!I15,'Athlète 9'!I15,'Athlète 10'!I15,'Athlète 11'!I15,'Athlète 12'!I15,'Athlète 13'!I15,'Athlète 14'!I15,'Athlète 15'!I15,'Athlète 16'!I15,'Athlète 17'!I15,'Athlète 18'!I15,'Athlète 19'!I15,'Athlète 20'!I15,'Athlète 21'!I15,'Athlète 22'!I15,'Athlète 23'!I15,'Athlète 24'!I15,'Athlète 25'!I15,'Athlète 26'!I15,'Athlète 27'!I15,'Athlète 28'!I15,'Athlète 29'!I15,'Athlète 30'!I15) -> 0 | C13: =AVERAGE('Athlète 1'!M15,'Athlète 2'!M15,'Athlète 3'!M15,'Athlète 4'!M15,'Athlète 5'!M15,'Athlète 6'!M15,'Athlète 7'!M15,'Athlète 8'!M15,'Athlète 9'!M15,'Athlète 10'!M15,'Athlète 11'!M15,'Athlète 12'!M15,'Athlète 13'!M15,'Athlète 14'!M15,'Athlète 15'!M15,'Athlète 16'!M15,'Athlète 17'!M15,'Athlète 18'!M15,'Athlète 19'!M15,'Athlète 20'!M15,'Athlète 21'!M15,'Athlète 22'!M15,'Athlète 23'!M15,'Athlète 24'!M15,'Athlète 25'!M15,'Athlète 26'!M15,'Athlète 27'!M15,'Athlète 28'!M15,'Athlète 29'!M15,'Athlète 30'!M15) -> 0 | D13: =IFERROR(AVERAGE('Athlète 1'!L15,'Athlète 2'!L15,'Athlète 3'!L15,'Athlète 4'!L15,'Athlète 5'!L15,'Athlète 6'!L15,'Athlète 7'!L15,'Athlète 8'!L15,'Athlète 9'!L15,'Athlète 10'!L15,'Athlète 11'!L15,'Athlète 12'!L15,'Athlète 13'!L15,'Athlète 14'!L15,'Athlète 15'!L15,'Athlète 16'!L15,'Athlète 17'!L15,'Athlète 18'!L15,'Athlète 19'!L15,'Athlète 20'!L15,'Athlète 21'!L15,'Athlète 22'!L15,'Athlète 23'!L15,'Athlète 24'!L15,'Athlète 25'!L15,'Athlète 26'!L15,'Athlète 27'!L15,'Athlète 28'!L15,'Athlète 29'!L15,'Athlète 30'!L15),"")
A14: ='Athlète 1'!A16 -> 46232 | B14: =AVERAGE('Athlète 1'!I16,'Athlète 2'!I16,'Athlète 3'!I16,'Athlète 4'!I16,'Athlète 5'!I16,'Athlète 6'!I16,'Athlète 7'!I16,'Athlète 8'!I16,'Athlète 9'!I16,'Athlète 10'!I16,'Athlète 11'!I16,'Athlète 12'!I16,'Athlète 13'!I16,'Athlète 14'!I16,'Athlète 15'!I16,'Athlète 16'!I16,'Athlète 17'!I16,'Athlète 18'!I16,'Athlète 19'!I16,'Athlète 20'!I16,'Athlète 21'!I16,'Athlète 22'!I16,'Athlète 23'!I16,'Athlète 24'!I16,'Athlète 25'!I16,'Athlète 26'!I16,'Athlète 27'!I16,'Athlète 28'!I16,'Athlète 29'!I16,'Athlète 30'!I16) -> 0 | C14: =AVERAGE('Athlète 1'!M16,'Athlète 2'!M16,'Athlète 3'!M16,'Athlète 4'!M16,'Athlète 5'!M16,'Athlète 6'!M16,'Athlète 7'!M16,'Athlète 8'!M16,'Athlète 9'!M16,'Athlète 10'!M16,'Athlète 11'!M16,'Athlète 12'!M16,'Athlète 13'!M16,'Athlète 14'!M16,'Athlète 15'!M16,'Athlète 16'!M16,'Athlète 17'!M16,'Athlète 18'!M16,'Athlète 19'!M16,'Athlète 20'!M16,'Athlète 21'!M16,'Athlète 22'!M16,'Athlète 23'!M16,'Athlète 24'!M16,'Athlète 25'!M16,'Athlète 26'!M16,'Athlète 27'!M16,'Athlète 28'!M16,'Athlète 29'!M16,'Athlète 30'!M16) -> 0 | D14: =IFERROR(AVERAGE('Athlète 1'!L16,'Athlète 2'!L16,'Athlète 3'!L16,'Athlète 4'!L16,'Athlète 5'!L16,'Athlète 6'!L16,'Athlète 7'!L16,'Athlète 8'!L16,'Athlète 9'!L16,'Athlète 10'!L16,'Athlète 11'!L16,'Athlète 12'!L16,'Athlète 13'!L16,'Athlète 14'!L16,'Athlète 15'!L16,'Athlète 16'!L16,'Athlète 17'!L16,'Athlète 18'!L16,'Athlète 19'!L16,'Athlète 20'!L16,'Athlète 21'!L16,'Athlète 22'!L16,'Athlète 23'!L16,'Athlète 24'!L16,'Athlète 25'!L16,'Athlète 26'!L16,'Athlète 27'!L16,'Athlète 28'!L16,'Athlète 29'!L16,'Athlète 30'!L16),"")
A15: ='Athlète 1'!A17 -> 46233 | B15: =AVERAGE('Athlète 1'!I17,'Athlète 2'!I17,'Athlète 3'!I17,'Athlète 4'!I17,'Athlète 5'!I17,'Athlète 6'!I17,'Athlète 7'!I17,'Athlète 8'!I17,'Athlète 9'!I17,'Athlète 10'!I17,'Athlète 11'!I17,'Athlète 12'!I17,'Athlète 13'!I17,'Athlète 14'!I17,'Athlète 15'!I17,'Athlète 16'!I17,'Athlète 17'!I17,'Athlète 18'!I17,'Athlète 19'!I17,'Athlète 20'!I17,'Athlète 21'!I17,'Athlète 22'!I17,'Athlète 23'!I17,'Athlète 24'!I17,'Athlète 25'!I17,'Athlète 26'!I17,'Athlète 27'!I17,'Athlète 28'!I17,'Athlète 29'!I17,'Athlète 30'!I17) -> 0.875 | C15: =AVERAGE('Athlète 1'!M17,'Athlète 2'!M17,'Athlète 3'!M17,'Athlète 4'!M17,'Athlète 5'!M17,'Athlète 6'!M17,'Athlète 7'!M17,'Athlète 8'!M17,'Athlète 9'!M17,'Athlète 10'!M17,'Athlète 11'!M17,'Athlète 12'!M17,'Athlète 13'!M17,'Athlète 14'!M17,'Athlète 15'!M17,'Athlète 16'!M17,'Athlète 17'!M17,'Athlète 18'!M17,'Athlète 19'!M17,'Athlète 20'!M17,'Athlète 21'!M17,'Athlète 22'!M17,'Athlète 23'!M17,'Athlète 24'!M17,'Athlète 25'!M17,'Athlète 26'!M17,'Athlète 27'!M17,'Athlète 28'!M17,'Athlète 29'!M17,'Athlète 30'!M17) -> 0.80208333 | D15: =IFERROR(AVERAGE('Athlète 1'!L17,'Athlète 2'!L17,'Athlète 3'!L17,'Athlète 4'!L17,'Athlète 5'!L17,'Athlète 6'!L17,'Athlète 7'!L17,'Athlète 8'!L17,'Athlète 9'!L17,'Athlète 10'!L17,'Athlète 11'!L17,'Athlète 12'!L17,'Athlète 13'!L17,'Athlète 14'!L17,'Athlète 15'!L17,'Athlète 16'!L17,'Athlète 17'!L17,'Athlète 18'!L17,'Athlète 19'!L17,'Athlète 20'!L17,'Athlète 21'!L17,'Athlète 22'!L17,'Athlète 23'!L17,'Athlète 24'!L17,'Athlète 25'!L17,'Athlète 26'!L17,'Athlète 27'!L17,'Athlète 28'!L17,'Athlète 29'!L17,'Athlète 30'!L17),"") -> 12
... A169: ='Athlète 1'!A171 -> 46387 | B169: =AVERAGE('Athlète 1'!I171,'Athlète 2'!I171,'Athlète 3'!I171,'Athlète 4'!I171,'Athlète 5'!I171,'Athlète 6'!I171,'Athlète 7'!I171,'Athlète 8'!I171,'Athlète 9'!I171,'Athlète 10'!I171,'Athlète 11'!I171,'Athlète 12'!I171,'Athlète 13'!I171,'Athlète 14'!I171,'Athlète 15'!I171,'Athlète 16'!I171,'Athlète 17'!I171,'Athlète 18'!I171,'Athlète 19'!I171,'Athlète 20'!I171,'Athlète 21'!I171,'Athlète 22'!I171,'Athlète 23'!I171,'Athlète 24'!I171,'Athlète 25'!I171,'Athlète 26'!I171,'Athlète 27'!I171,'Athlète 28'!I171,'Athlète 29'!I171,'Athlète 30'!I171) -> 0 | C169: =AVERAGE('Athlète 1'!M171,'Athlète 2'!M171,'Athlète 3'!M171,'Athlète 4'!M171,'Athlète 5'!M171,'Athlète 6'!M171,'Athlète 7'!M171,'Athlète 8'!M171,'Athlète 9'!M171,'Athlète 10'!M171,'Athlète 11'!M171,'Athlète 12'!M171,'Athlète 13'!M171,'Athlète 14'!M171,'Athlète 15'!M171,'Athlète 16'!M171,'Athlète 17'!M171,'Athlète 18'!M171,'Athlète 19'!M171,'Athlète 20'!M171,'Athlète 21'!M171,'Athlète 22'!M171,'Athlète 23'!M171,'Athlète 24'!M171,'Athlète 25'!M171,'Athlète 26'!M171,'Athlète 27'!M171,'Athlète 28'!M171,'Athlète 29'!M171,'Athlète 30'!M171) -> 65.061339 | D169: =IFERROR(AVERAGE('Athlète 1'!L171,'Athlète 2'!L171,'Athlète 3'!L171,'Athlète 4'!L171,'Athlète 5'!L171,'Athlète 6'!L171,'Athlète 7'!L171,'Athlète 8'!L171,'Athlète 9'!L171,'Athlète 10'!L171,'Athlète 11'!L171,'Athlète 12'!L171,'Athlète 13'!L171,'Athlète 14'!L171,'Athlète 15'!L171,'Athlète 16'!L171,'Athlète 17'!L171,'Athlète 18'!L171,'Athlète 19'!L171,'Athlète 20'!L171,'Athlète 21'!L171,'Athlète 22'!L171,'Athlète 23'!L171,'Athlète 24'!L171,'Athlète 25'!L171,'Athlète 26'!L171,'Athlète 27'!L171,'Athlète 28'!L171,'Athlète 29'!L171,'Athlète 30'!L171),"")

Sheet Athlète 1
A1: 🏠 Dashboard | B1: ◀ Précédent | C1: Suivant ▶
A3: FICHE ATHLÈTE 1 | F3: Nom du joueur : | G3: Athlète 1
A5: Date | B5: Jour | C5: Semaine | D5: Mois | E5: Année | F5: Type de séance | G5: RPE | H5: Durée (h) | I5: CT | J5: Charge aiguë | K5: Charge chronique | L5: ACWR | M5: Fatigue | N5: Commentaires
A6: 46222 | B6: =TEXT(A6,"dddd") -> dddd | C6: =WEEKNUM(A6,2) -> 29 | D6: =TEXT(A6,"mmmm") -> juillet | E6: =YEAR(A6) -> 2026 | I6: =IF(OR(G6="",H6=""),0,G6*H6) -> 0 | J6: =SUM(I$6:I6) -> 0 | K6: =AVERAGE(I$6:I6) -> 0 | L6: =IF(K6=0,"",J6/K6) | M6: =MAX(0,0+(J6-K6)) -> 0
A7: 46223 | B7: =TEXT(A7,"dddd") -> dddd | C7: =WEEKNUM(A7,2) -> 30 | D7: =TEXT(A7,"mmmm") -> juillet | E7: =YEAR(A7) -> 2026 | I7: =IF(OR(G7="",H7=""),0,G7*H7) -> 0 | J7: =SUM(I$6:I7) -> 0 | K7: =AVERAGE(I$6:I7) -> 0 | L7: =IF(K7=0,"",J7/K7) | M7: =MAX(0,M6+(J7-K7)) -> 0
A8: 46224 | B8: =TEXT(A8,"dddd") -> dddd | C8: =WEEKNUM(A8,2) -> 30 | D8: =TEXT(A8,"mmmm") -> juillet | E8: =YEAR(A8) -> 2026 | I8: =IF(OR(G8="",H8=""),0,G8*H8) -> 0 | J8: =SUM(I$6:I8) -> 0 | K8: =AVERAGE(I$6:I8) -> 0 | L8: =IF(K8=0,"",J8/K8) | M8: =MAX(0,M7+(J8-K8)) -> 0
A9: 46225 | B9: =TEXT(A9,"dddd") -> dddd | C9: =WEEKNUM(A9,2) -> 30 | D9: =TEXT(A9,"mmmm") -> juillet | E9: =YEAR(A9) -> 2026 | I9: =IF(OR(G9="",H9=""),0,G9*H9) -> 0 | J9: =SUM(I$6:I9) -> 0 | K9: =AVERAGE(I$6:I9) -> 0 | L9: =IF(K9=0,"",J9/K9) | M9: =MAX(0,M8+(J9-K9)) -> 0
A10: 46226 | B10: =TEXT(A10,"dddd") -> dddd | C10: =WEEKNUM(A10,2) -> 30 | D10: =TEXT(A10,"mmmm") -> juillet | E10: =YEAR(A10) -> 2026 | I10: =IF(OR(G10="",H10=""),0,G10*H10) -> 0 | J10: =SUM(I$6:I10) -> 0 | K10: =AVERAGE(I$6:I10) -> 0 | L10: =IF(K10=0,"",J10/K10) | M10: =MAX(0,M9+(J10-K10)) -> 0
A11: 46227 | B11: =TEXT(A11,"dddd") -> dddd | C11: =WEEKNUM(A11,2) -> 30 | D11: =TEXT(A11,"mmmm") -> juillet | E11: =YEAR(A11) -> 2026 | I11: =IF(OR(G11="",H11=""),0,G11*H11) -> 0 | J11: =SUM(I$6:I11) -> 0 | K11: =AVERAGE(I$6:I11) -> 0 | L11: =IF(K11=0,"",J11/K11) | M11: =MAX(0,M10+(J11-K11)) -> 0
A12: 46228 | B12: =TEXT(A12,"dddd") -> dddd | C12: =WEEKNUM(A12,2) -> 30 | D12: =TEXT(A12,"mmmm") -> juillet | E12: =YEAR(A12) -> 2026 | I12: =IF(OR(G12="",H12=""),0,G12*H12) -> 0 | J12: =SUM(I6:I12) -> 0 | K12: =AVERAGE(I$6:I12) -> 0 | L12: =IF(K12=0,"",J12/K12) | M12: =MAX(0,M11+(J12-K12)) -> 0
A13: 46229 | B13: =TEXT(A13,"dddd") -> dddd | C13: =WEEKNUM(A13,2) -> 30 | D13: =TEXT(A13,"mmmm") -> juillet | E13: =YEAR(A13) -> 2026 | I13: =IF(OR(G13="",H13=""),0,G13*H13) -> 0 | J13: =SUM(I7:I13) -> 0 | K13: =AVERAGE(I$6:I13) -> 0 | L13: =IF(K13=0,"",J13/K13) | M13: =MAX(0,M12+(J13-K13)) -> 0
A14: 46230 | B14: =TEXT(A14,"dddd") -> dddd | C14: =WEEKNUM(A14,2) -> 31 | D14: =TEXT(A14,"mmmm") -> juillet | E14: =YEAR(A14) -> 2026 | I14: =IF(OR(G14="",H14=""),0,G14*H14) -> 0 | J14: =SUM(I8:I14) -> 0 | K14: =AVERAGE(I$6:I14) -> 0 | L14: =IF(K14=0,"",J14/K14) | M14: =MAX(0,M13+(J14-K14)) -> 0
A15: 46231 | B15: =TEXT(A15,"dddd") -> dddd | C15: =WEEKNUM(A15,2) -> 31 | D15: =TEXT(A15,"mmmm") -> juillet | E15: =YEAR(A15) -> 2026 | I15: =IF(OR(G15="",H15=""),0,G15*H15) -> 0 | J15: =SUM(I9:I15) -> 0 | K15: =AVERAGE(I$6:I15) -> 0 | L15: =IF(K15=0,"",J15/K15) | M15: =MAX(0,M14+(J15-K15)) -> 0
A16: 46232 | B16: =TEXT(A16,"dddd") -> dddd | C16: =WEEKNUM(A16,2) -> 31 | D16: =TEXT(A16,"mmmm") -> juillet | E16: =YEAR(A16) -> 2026 | I16: =IF(OR(G16="",H16=""),0,G16*H16) -> 0 | J16: =SUM(I10:I16) -> 0 | K16: =AVERAGE(I$6:I16) -> 0 | L16: =IF(K16=0,"",J16/K16) | M16: =MAX(0,M15+(J16-K16)) -> 0
A17: 46233 | B17: =TEXT(A17,"dddd") -> dddd | C17: =WEEKNUM(A17,2) -> 31 | D17: =TEXT(A17,"mmmm") -> juillet | E17: =YEAR(A17) -> 2026 | G17: 15 | H17: 1.75 | I17: =IF(OR(G17="",H17=""),0,G17*H17) -> 26.25 | J17: =SUM(I11:I17) -> 26.25 | K17: =AVERAGE(I$6:I17) -> 2.1875 | L17: =IF(K17=0,"",J17/K17) -> 12 | M17: =MAX(0,M16+(J17-K17)) -> 24.0625
A18: 46234 | B18: =TEXT(A18,"dddd") -> dddd | C18: =WEEKNUM(A18,2) -> 31 | D18: =TEXT(A18,"mmmm") -> juillet | E18: =YEAR(A18) -> 2026 | G18: 10.5 | H18: 3 | I18: =IF(OR(G18="",H18=""),0,G18*H18) -> 31.5 | J18: =SUM(I12:I18) -> 57.75 | K18: =AVERAGE(I$6:I18) -> 4.4423077 | L18: =IF(K18=0,"",J18/K18) -> 13 | M18: =MAX(0,M17+(J18-K18)) -> 77.370192
A19: 46235 | B19: =TEXT(A19,"dddd") -> dddd | C19: =WEEKNUM(A19,2) -> 31 | D19: =TEXT(A19,"mmmm") -> août | E19: =YEAR(A19) -> 2026 | G19: 0 | H19: 0 | I19: =IF(OR(G19="",H19=""),0,G19*H19) -> 0 | J19: =SUM(I13:I19) -> 57.75 | K19: =AVERAGE(I$6:I19) -> 4.125 | L19: =IF(K19=0,"",J19/K19) -> 14 | M19: =MAX(0,M18+(J19-K19)) -> 130.99519
A20: 46236 | B20: =TEXT(A20,"dddd") -> dddd | C20: =WEEKNUM(A20,2) -> 31 | D20: =TEXT(A20,"mmmm") -> août | E20: =YEAR(A20) -> 2026 | G20: 10 | H20: 1 | I20: =IF(OR(G20="",H20=""),0,G20*H20) -> 10 | J20: =SUM(I14:I20) -> 67.75 | K20: =AVERAGE(I$6:I20) -> 4.5166667 | L20: =IF(K20=0,"",J20/K20) -> 15 | M20: =MAX(0,M19+(J20-K20)) -> 194.22853
A21: 46237 | B21: =TEXT(A21,"dddd") -> dddd | C21: =WEEKNUM(A21,2) -> 32 | D21: =TEXT(A21,"mmmm") -> août | E21: =YEAR(A21) -> 2026 | G21: 11 | H21: 2 | I21: =IF(OR(G21="",H21=""),0,G21*H21) -> 22 | J21: =SUM(I15:I21) -> 89.75 | K21: =AVERAGE(I$6:I21) -> 5.609375 | L21: =IF(K21=0,"",J21/K21) -> 16 | M21: =MAX(0,M20+(J21-K21)) -> 278.36915
A22: 46238 | B22: =TEXT(A22,"dddd") -> dddd | C22: =WEEKNUM(A22,2) -> 32 | D22: =TEXT(A22,"mmmm") -> août | E22: =YEAR(A22) -> 2026 | G22: 7 | H22: 0.41 | I22: =IF(OR(G22="",H22=""),0,G22*H22) -> 2.87 | J22: =SUM(I16:I22) -> 92.62 | K22: =AVERAGE(I$6:I22) -> 5.4482353 | L22: =IF(K22=0,"",J22/K22) -> 17 | M22: =MAX(0,M21+(J22-K22)) -> 365.54092
A23: 46239 | B23: =TEXT(A23,"dddd") -> dddd | C23: =WEEKNUM(A23,2) -> 32 | D23: =TEXT(A23,"mmmm") -> août | E23: =YEAR(A23) -> 2026 | G23: 0.25 | H23: 6 | I23: =IF(OR(G23="",H23=""),0,G23*H23) -> 1.5 | J23: =SUM(I17:I23) -> 94.12 | K23: =AVERAGE(I$6:I23) -> 5.2288889 | L23: =IF(K23=0,"",J23/K23) -> 18 | M23: =MAX(0,M22+(J23-K23)) -> 454.43203
A24: 46240 | B24: =TEXT(A24,"dddd") -> dddd | C24: =WEEKNUM(A24,2) -> 32 | D24: =TEXT(A24,"mmmm") -> août | E24: =YEAR(A24) -> 2026 | G24: 7 | H24: 0.5 | I24: =IF(OR(G24="",H24=""),0,G24*H24) -> 3.5 | J24: =SUM(I18:I24) -> 71.37 | K24: =AVERAGE(I$6:I24) -> 5.1378947 | L24: =IF(K24=0,"",J24/K24) -> 13.890904 | M24: =MAX(0,M23+(J24-K24)) -> 520.66413
A25: 46241 | B25: =TEXT(A25,"dddd") -> dddd | C25: =WEEKNUM(A25,2) -> 32 | D25: =TEXT(A25,"mmmm") -> août | E25: =YEAR(A25) -> 2026 | G25: 0 | H25: 0 | I25: =IF(OR(G25="",H25=""),0,G25*H25) -> 0 | J25: =SUM(I19:I25) -> 39.87 | K25: =AVERAGE(I$6:I25) -> 4.881 | L25: =IF(K25=0,"",J25/K25) -> 8.1684081 | M25: =MAX(0,M24+(J25-K25)) -> 555.65313
A26: 46242 | B26: =TEXT(A26,"dddd") -> dddd | C26: =WEEKNUM(A26,2) -> 32 | D26: =TEXT(A26,"mmmm") -> août | E26: =YEAR(A26) -> 2026 | G26: 15 | H26: 3 | I26: =IF(OR(G26="",H26=""),0,G26*H26) -> 45 | J26: =SUM(I20:I26) -> 84.87 | K26: =AVERAGE(I$6:I26) -> 6.7914286 | L26: =IF(K26=0,"",J26/K26) -> 12.496634 | M26: =MAX(0,M25+(J26-K26)) -> 633.7317
A27: 46243 | B27: =TEXT(A27,"dddd") -> dddd | C27: =WEEKNUM(A27,2) -> 32 | D27: =TEXT(A27,"mmmm") -> août | E27: =YEAR(A27) -> 2026 | G27: 9 | H27: 1.25 | I27: =IF(OR(G27="",H27=""),0,G27*H27) -> 11.25 | J27: =SUM(I21:I27) -> 86.12 | K27: =AVERAGE(I$6:I27) -> 6.9940909 | L27: =IF(K27=0,"",J27/K27) -> 12.313251 | M27: =MAX(0,M26+(J27-K27)) -> 712.85761
A28: 46244 | B28: =TEXT(A28,"dddd") -> dddd | C28: =WEEKNUM(A28,2) -> 33 | D28: =TEXT(A28,"mmmm") -> août | E28: =YEAR(A28) -> 2026 | G28: 13.3 | H28: 3 | I28: =IF(OR(G28="",H28=""),0,G28*H28) -> 39.9 | J28: =SUM(I22:I28) -> 104.02 | K28: =AVERAGE(I$6:I28) -> 8.4247826 | L28: =IF(K28=0,"",J28/K28) -> 12.346906 | M28: =MAX(0,M27+(J28-K28)) -> 808.45283
... A32: 46248 | B32: =TEXT(A32,"dddd") -> dddd | C32: =WEEKNUM(A32,2) -> 33 | D32: =TEXT(A32,"mmmm") -> août | E32: =YEAR(A32) -> 2026 | G32: 10 | H32: 0.75 | I32: =IF(OR(G32="",H32=""),0,G32*H32) -> 7.5 | J32: =SUM(I26:I32) -> 118.7 | K32: =AVERAGE(I$6:I32) -> 8.0118519 | L32: =IF(K32=0,"",J32/K32) -> 14.815551 | M32: =MAX(0,M31+(J32-K32)) -> 1221.662
A33: 46249 | B33: =TEXT(A33,"dddd") -> dddd | C33: =WEEKNUM(A33,2) -> 33 | D33: =TEXT(A33,"mmmm") -> août | E33: =YEAR(A33) -> 2026 | G33: 12 | H33: 1.57 | I33: =IF(OR(G33="",H33=""),0,G33*H33) -> 18.84 | J33: =SUM(I27:I33) -> 92.54 | K33: =AVERAGE(I6:I33) -> 8.3985714 | L33: =IF(K33=0,"",J33/K33) -> 11.018541 | M33: =MAX(0,M32+(J33-K33)) -> 1305.8034
A34: 46250 | B34: =TEXT(A34,"dddd") -> dddd | C34: =WEEKNUM(A34,2) -> 33 | D34: =TEXT(A34,"mmmm") -> août | E34: =YEAR(A34) -> 2026 | G34: 15 | H34: 2.75 | I34: =IF(OR(G34="",H34=""),0,G34*H34) -> 41.25 | J34: =SUM(I28:I34) -> 122.54 | K34: =AVERAGE(I7:I34) -> 9.8717857 | L34: =IF(K34=0,"",J34/K34) -> 12.413154 | M34: =MAX(0,M33+(J34-K34)) -> 1418.4716
A35: 46251 | B35: =TEXT(A35,"dddd") -> dddd | C35: =WEEKNUM(A35,2) -> 34 | D35: =TEXT(A35,"mmmm") -> août | E35: =YEAR(A35) -> 2026 | G35: 10 | H35: 1.25 | I35: =IF(OR(G35="",H35=""),0,G35*H35) -> 12.5 | J35: =SUM(I29:I35) -> 95.14 | K35: =AVERAGE(I8:I35) -> 10.318214 | L35: =IF(K35=0,"",J35/K35) -> 9.2205877 | M35: =MAX(0,M34+(J35-K35)) -> 1503.2934
A36: 46252 | B36: =TEXT(A36,"dddd") -> dddd | C36: =WEEKNUM(A36,2) -> 34 | D36: =TEXT(A36,"mmmm") -> août | E36: =YEAR(A36) -> 2026 | G36: 0 | H36: 0 | I36: =IF(OR(G36="",H36=""),0,G36*H36) -> 0 | J36: =SUM(I30:I36) -> 92.9 | K36: =AVERAGE(I9:I36) -> 10.318214 | L36: =IF(K36=0,"",J36/K36) -> 9.0034959 | M36: =MAX(0,M35+(J36-K36)) -> 1585.8752
A37: 46253 | B37: =TEXT(A37,"dddd") -> dddd | C37: =WEEKNUM(A37,2) -> 34 | D37: =TEXT(A37,"mmmm") -> août | E37: =YEAR(A37) -> 2026 | G37: 0 | H37: 0 | I37: =IF(OR(G37="",H37=""),0,G37*H37) -> 0 | J37: =SUM(I31:I37) -> 82.4 | K37: =AVERAGE(I10:I37) -> 10.318214 | L37: =IF(K37=0,"",J37/K37) -> 7.985878 | M37: =MAX(0,M36+(J37-K37)) -> 1657.957
A38: 46254 | B38: =TEXT(A38,"dddd") -> dddd | C38: =WEEKNUM(A38,2) -> 34 | D38: =TEXT(A38,"mmmm") -> août | E38: =YEAR(A38) -> 2026 | G38: 14 | H38: 2 | I38: =IF(OR(G38="",H38=""),0,G38*H38) -> 28 | J38: =SUM(I32:I38) -> 108.09 | K38: =AVERAGE(I11:I38) -> 11.318214 | L38: =IF(K38=0,"",J38/K38) -> 9.5500931 | M38: =MAX(0,M37+(J38-K38)) -> 1754.7287
A39: 46255 | B39: =TEXT(A39,"dddd") -> dddd | C39: =WEEKNUM(A39,2) -> 34 | D39: =TEXT(A39,"mmmm") -> août | E39: =YEAR(A39) -> 2026 | G39: 10 | H39: 0.5 | I39: =IF(OR(G39="",H39=""),0,G39*H39) -> 5 | J39: =SUM(I33:I39) -> 105.59 | K39: =AVERAGE(I12:I39) -> 11.496786 | L39: =IF(K39=0,"",J39/K39) -> 9.1843062 | M39: =MAX(0,M38+(J39-K39)) -> 1848.822
A40: 46256 | B40: =TEXT(A40,"dddd") -> dddd | C40: =WEEKNUM(A40,2) -> 34 | D40: =TEXT(A40,"mmmm") -> août | E40: =YEAR(A40) -> 2026 | G40: 0 | H40: 0 | I40: =IF(OR(G40="",H40=""),0,G40*H40) -> 0 | J40: =SUM(I34:I40) -> 86.75 | K40: =AVERAGE(I13:I40) -> 11.496786 | L40: =IF(K40=0,"",J40/K40) -> 7.5455873 | M40: =MAX(0,M39+(J40-K40)) -> 1924.0752
A41: 46257 | B41: =TEXT(A41,"dddd") -> dddd | C41: =WEEKNUM(A41,2) -> 34 | D41: =TEXT(A41,"mmmm") -> août | E41: =YEAR(A41) -> 2026 | G41: 0 | H41: 0 | I41: =IF(OR(G41="",H41=""),0,G41*H41) -> 0 | J41: =SUM(I35:I41) -> 45.5 | K41: =AVERAGE(I14:I41) -> 11.496786 | L41: =IF(K41=0,"",J41/K41) -> 3.9576279 | M41: =MAX(0,M40+(J41-K41)) -> 1958.0784
A42: 46258 | B42: =TEXT(A42,"dddd") -> dddd | C42: =WEEKNUM(A42,2) -> 35 | D42: =TEXT(A42,"mmmm") -> août | E42: =YEAR(A42) -> 2026 | G42: 0 | H42: 0 | I42: =IF(OR(G42="",H42=""),0,G42*H42) -> 0 | J42: =SUM(I36:I42) -> 33 | K42: =AVERAGE(I15:I42) -> 11.496786 | L42: =IF(K42=0,"",J42/K42) -> 2.8703675 | M42: =MAX(0,M41+(J42-K42)) -> 1979.5816
A43: 46259 | B43: =TEXT(A43,"dddd") -> dddd | C43: =WEEKNUM(A43,2) -> 35 | D43: =TEXT(A43,"mmmm") -> août | E43: =YEAR(A43) -> 2026 | G43: 0 | H43: 0 | I43: =IF(OR(G43="",H43=""),0,G43*H43) -> 0 | J43: =SUM(I37:I43) -> 33 | K43: =AVERAGE(I16:I43) -> 11.496786 | L43: =IF(K43=0,"",J43/K43) -> 2.8703675 | M43: =MAX(0,M42+(J43-K43)) -> 2001.0848
A44: 46260 | B44: =TEXT(A44,"dddd") -> dddd | C44: =WEEKNUM(A44,2) -> 35 | D44: =TEXT(A44,"mmmm") -> août | E44: =YEAR(A44) -> 2026 | G44: 0 | H44: 0 | I44: =IF(OR(G44="",H44=""),0,G44*H44) -> 0 | J44: =SUM(I38:I44) -> 33 | K44: =AVERAGE(I17:I44) -> 11.496786 | L44: =IF(K44=0,"",J44/K44) -> 2.8703675 | M44: =MAX(0,M43+(J44-K44)) -> 2022.588
... A46: 46262 | B46: =TEXT(A46,"dddd") -> dddd | C46: =WEEKNUM(A46,2) -> 35 | D46: =TEXT(A46,"mmmm") -> août | E46: =YEAR(A46) -> 2026 | G46: 13 | H46: 0.58 | I46: =IF(OR(G46="",H46=""),0,G46*H46) -> 7.54 | J46: =SUM(I40:I46) -> 7.54 | K46: =AVERAGE(I19:I46) -> 9.7035714 | L46: =IF(K46=0,"",J46/K46) -> 0.77703349 | M46: =MAX(0,M45+(J46-K46)) -> 2014.8652
...

Sheet Athlète 2
A1: 🏠 Dashboard | B1: ◀ Précédent | C1: Suivant ▶
A3: FICHE ATHLÈTE 2 | F3: Nom du joueur : | G3: Athlète 2
A5: Date | B5: Jour | C5: Semaine | D5: Mois | E5: Année | F5: Type de séance | G5: RPE | H5: Durée (h) | I5: CT | J5: Charge aiguë | K5: Charge chronique | L5: ACWR | M5: Fatigue | N5: Commentaires
A6: 46222 | B6: =TEXT(A6,"dddd") -> dddd | C6: =WEEKNUM(A6,2) -> 29 | D6: =TEXT(A6,"mmmm") -> juillet | E6: =YEAR(A6) -> 2026 | I6: =IF(OR(G6="",H6=""),0,G6*H6) -> 0 | J6: =SUM(I$6:I6) -> 0 | K6: =AVERAGE(I$6:I6) -> 0 | L6: =IF(K6=0,"",J6/K6) | M6: =MAX(0,0+(J6-K6)) -> 0
A7: 46223 | B7: =TEXT(A7,"dddd") -> dddd | C7: =WEEKNUM(A7,2) -> 30 | D7: =TEXT(A7,"mmmm") -> juillet | E7: =YEAR(A7) -> 2026 | I7: =IF(OR(G7="",H7=""),0,G7*H7) -> 0 | J7: =SUM(I$6:I7) -> 0 | K7: =AVERAGE(I$6:I7) -> 0 | L7: =IF(K7=0,"",J7/K7) | M7: =MAX(0,M6+(J7-K7)) -> 0
A8: 46224 | B8: =TEXT(A8,"dddd") -> dddd | C8: =WEEKNUM(A8,2) -> 30 | D8: =TEXT(A8,"mmmm") -> juillet | E8: =YEAR(A8) -> 2026 | I8: =IF(OR(G8="",H8=""),0,G8*H8) -> 0 | J8: =SUM(I$6:I8) -> 0 | K8: =AVERAGE(I$6:I8) -> 0 | L8: =IF(K8=0,"",J8/K8) | M8: =MAX(0,M7+(J8-K8)) -> 0
A9: 46225 | B9: =TEXT(A9,"dddd") -> dddd | C9: =WEEKNUM(A9,2) -> 30 | D9: =TEXT(A9,"mmmm") -> juillet | E9: =YEAR(A9) -> 2026 | I9: =IF(OR(G9="",H9=""),0,G9*H9) -> 0 | J9: =SUM(I$6:I9) -> 0 | K9: =AVERAGE(I$6:I9) -> 0 | L9: =IF(K9=0,"",J9/K9) | M9: =MAX(0,M8+(J9-K9)) -> 0
A10: 46226 | B10: =TEXT(A10,"dddd") -> dddd | C10: =WEEKNUM(A10,2) -> 30 | D10: =TEXT(A10,"mmmm") -> juillet | E10: =YEAR(A10) -> 2026 | I10: =IF(OR(G10="",H10=""),0,G10*H10) -> 0 | J10: =SUM(I$6:I10) -> 0 | K10: =AVERAGE(I$6:I10) -> 0 | L10: =IF(K10=0,"",J10/K10) | M10: =MAX(0,M9+(J10-K10)) -> 0
A11: 46227 | B11: =TEXT(A11,"dddd") -> dddd | C11: =WEEKNUM(A11,2) -> 30 | D11: =TEXT(A11,"mmmm") -> juillet | E11: =YEAR(A11) -> 2026 | I11: =IF(OR(G11="",H11=""),0,G11*H11) -> 0 | J11: =SUM(I$6:I11) -> 0 | K11: =AVERAGE(I$6:I11) -> 0 | L11: =IF(K11=0,"",J11/K11) | M11: =MAX(0,M10+(J11-K11)) -> 0
A12: 46228 | B12: =TEXT(A12,"dddd") -> dddd | C12: =WEEKNUM(A12,2) -> 30 | D12: =TEXT(A12,"mmmm") -> juillet | E12: =YEAR(A12) -> 2026 | I12: =IF(OR(G12="",H12=""),0,G12*H12) -> 0 | J12: =SUM(I6:I12) -> 0 | K12: =AVERAGE(I$6:I12) -> 0 | L12: =IF(K12=0,"",J12/K12) | M12: =MAX(0,M11+(J12-K12)) -> 0
A13: 46229 | B13: =TEXT(A13,"dddd") -> dddd | C13: =WEEKNUM(A13,2) -> 30 | D13: =TEXT(A13,"mmmm") -> juillet | E13: =YEAR(A13) -> 2026 | I13: =IF(OR(G13="",H13=""),0,G13*H13) -> 0 | J13: =SUM(I7:I13) -> 0 | K13: =AVERAGE(I$6:I13) -> 0 | L13: =IF(K13=0,"",J13/K13) | M13: =MAX(0,M12+(J13-K13)) -> 0
A14: 46230 | B14: =TEXT(A14,"dddd") -> dddd | C14: =WEEKNUM(A14,2) -> 31 | D14: =TEXT(A14,"mmmm") -> juillet | E14: =YEAR(A14) -> 2026 | I14: =IF(OR(G14="",H14=""),0,G14*H14) -> 0 | J14: =SUM(I8:I14) -> 0 | K14: =AVERAGE(I$6:I14) -> 0 | L14: =IF(K14=0,"",J14/K14) | M14: =MAX(0,M13+(J14-K14)) -> 0
A15: 46231 | B15: =TEXT(A15,"dddd") -> dddd | C15: =WEEKNUM(A15,2) -> 31 | D15: =TEXT(A15,"mmmm") -> juillet | E15: =YEAR(A15) -> 2026 | I15: =IF(OR(G15="",H15=""),0,G15*H15) -> 0 | J15: =SUM(I9:I15) -> 0 | K15: =AVERAGE(I$6:I15) -> 0 | L15: =IF(K15=0,"",J15/K15) | M15: =MAX(0,M14+(J15-K15)) -> 0
A16: 46232 | B16: =TEXT(A16,"dddd") -> dddd | C16: =WEEKNUM(A16,2) -> 31 | D16: =TEXT(A16,"mmmm") -> juillet | E16: =YEAR(A16) -> 2026 | I16: =IF(OR(G16="",H16=""),0,G16*H16) -> 0 | J16: =SUM(I10:I16) -> 0 | K16: =AVERAGE(I$6:I16) -> 0 | L16: =IF(K16=0,"",J16/K16) | M16: =MAX(0,M15+(J16-K16)) -> 0
A17: 46233 | B17: =TEXT(A17,"dddd") -> dddd | C17: =WEEKNUM(A17,2) -> 31 | D17: =TEXT(A17,"mmmm") -> juillet | E17: =YEAR(A17) -> 2026 | I17: =IF(OR(G17="",H17=""),0,G17*H17) -> 0 | J17: =SUM(I11:I17) -> 0 | K17: =AVERAGE(I$6:I17) -> 0 | L17: =IF(K17=0,"",J17/K17) | M17: =MAX(0,M16+(J17-K17)) -> 0
A18: 46234 | B18: =TEXT(A18,"dddd") -> dddd | C18: =WEEKNUM(A18,2) -> 31 | D18: =TEXT(A18,"mmmm") -> juillet | E18: =YEAR(A18) -> 2026 | I18: =IF(OR(G18="",H18=""),0,G18*H18) -> 0 | J18: =SUM(I12:I18) -> 0 | K18: =AVERAGE(I$6:I18) -> 0 | L18: =IF(K18=0,"",J18/K18) | M18: =MAX(0,M17+(J18-K18)) -> 0
A19: 46235 | B19: =TEXT(A19,"dddd") -> dddd | C19: =WEEKNUM(A19,2) -> 31 | D19: =TEXT(A19,"mmmm") -> août | E19: =YEAR(A19) -> 2026 | I19: =IF(OR(G19="",H19=""),0,G19*H19) -> 0 | J19: =SUM(I13:I19) -> 0 | K19: =AVERAGE(I$6:I19) -> 0 | L19: =IF(K19=0,"",J19/K19) | M19: =MAX(0,M18+(J19-K19)) -> 0
A20: 46236 | B20: =TEXT(A20,"dddd") -> dddd | C20: =WEEKNUM(A20,2) -> 31 | D20: =TEXT(A20,"mmmm") -> août | E20: =YEAR(A20) -> 2026 | I20: =IF(OR(G20="",H20=""),0,G20*H20) -> 0 | J20: =SUM(I14:I20) -> 0 | K20: =AVERAGE(I$6:I20) -> 0 | L20: =IF(K20=0,"",J20/K20) | M20: =MAX(0,M19+(J20-K20)) -> 0
A21: 46237 | B21: =TEXT(A21,"dddd") -> dddd | C21: =WEEKNUM(A21,2) -> 32 | D21: =TEXT(A21,"mmmm") -> août | E21: =YEAR(A21) -> 2026 | I21: =IF(OR(G21="",H21=""),0,G21*H21) -> 0 | J21: =SUM(I15:I21) -> 0 | K21: =AVERAGE(I$6:I21) -> 0 | L21: =IF(K21=0,"",J21/K21) | M21: =MAX(0,M20+(J21-K21)) -> 0
A22: 46238 | B22: =TEXT(A22,"dddd") -> dddd | C22: =WEEKNUM(A22,2) -> 32 | D22: =TEXT(A22,"mmmm") -> août | E22: =YEAR(A22) -> 2026 | I22: =IF(OR(G22="",H22=""),0,G22*H22) -> 0 | J22: =SUM(I16:I22) -> 0 | K22: =AVERAGE(I$6:I22) -> 0 | L22: =IF(K22=0,"",J22/K22) | M22: =MAX(0,M21+(J22-K22)) -> 0
A23: 46239 | B23: =TEXT(A23,"dddd") -> dddd | C23: =WEEKNUM(A23,2) -> 32 | D23: =TEXT(A23,"mmmm") -> août | E23: =YEAR(A23) -> 2026 | I23: =IF(OR(G23="",H23=""),0,G23*H23) -> 0 | J23: =SUM(I17:I23) -> 0 | K23: =AVERAGE(I$6:I23) -> 0 | L23: =IF(K23=0,"",J23/K23) | M23: =MAX(0,M22+(J23-K23)) -> 0
... A32: 46248 | B32: =TEXT(A32,"dddd") -> dddd | C32: =WEEKNUM(A32,2) -> 33 | D32: =TEXT(A32,"mmmm") -> août | E32: =YEAR(A32) -> 2026 | I32: =IF(OR(G32="",H32=""),0,G32*H32) -> 0 | J32: =SUM(I26:I32) -> 0 | K32: =AVERAGE(I$6:I32) -> 0 | L32: =IF(K32=0,"",J32/K32) | M32: =MAX(0,M31+(J32-K32)) -> 0
A33: 46249 | B33: =TEXT(A33,"dddd") -> dddd | C33: =WEEKNUM(A33,2) -> 33 | D33: =TEXT(A33,"mmmm") -> août | E33: =YEAR(A33) -> 2026 | I33: =IF(OR(G33="",H33=""),0,G33*H33) -> 0 | J33: =SUM(I27:I33) -> 0 | K33: =AVERAGE(I6:I33) -> 0 | L33: =IF(K33=0,"",J33/K33) | M33: =MAX(0,M32+(J33-K33)) -> 0
A34: 46250 | B34: =TEXT(A34,"dddd") -> dddd | C34: =WEEKNUM(A34,2) -> 33 | D34: =TEXT(A34,"mmmm") -> août | E34: =YEAR(A34) -> 2026 | I34: =IF(OR(G34="",H34=""),0,G34*H34) -> 0 | J34: =SUM(I28:I34) -> 0 | K34: =AVERAGE(I7:I34) -> 0 | L34: =IF(K34=0,"",J34/K34) | M34: =MAX(0,M33+(J34-K34)) -> 0
A35: 46251 | B35: =TEXT(A35,"dddd") -> dddd | C35: =WEEKNUM(A35,2) -> 34 | D35: =TEXT(A35,"mmmm") -> août | E35: =YEAR(A35) -> 2026 | I35: =IF(OR(G35="",H35=""),0,G35*H35) -> 0 | J35: =SUM(I29:I35) -> 0 | K35: =AVERAGE(I8:I35) -> 0 | L35: =IF(K35=0,"",J35/K35) | M35: =MAX(0,M34+(J35-K35)) -> 0
